Workbook

Sheet README
A1: SCW BUDGETING & PROJECTIONS TOOL — 2026
A2: Built 2026-08-21 from: Xero General Ledger Detail (Jan 1 – Aug 21 2026, accrual), the legacy budgeting tool exports (contractsexpenses.csv + allocations.csv), and the legacy BUDGET workbook (staffing roster, sales roster, ramp schedules).
A4: HOW THE TABS FIT TOGETHER
A5: PROJECTIONS — the leadership view. Actual months show Xero as booked; projected months are driven by the three control tabs. Modest and stretch scenarios display side by side.
A6: SALES TEAM — one row per rep. Set MODEST % and STRETCH % attainment per person (e.g. Zach 80% / Stu 100%), ramp curve and start month. Rep commissions + Sales Manager + Director overrides = the comp liability that flows to PROJECTIONS.
A7: STAFFING — headcount × fully-loaded monthly cost for every role. Model hires/exits by editing monthly headcount or adding rows; raise levers: per-role $ or %, or department-wide % (table at the bottom), from a chosen month.
A8: EXPENSES — every recurring cost with ON/OFF, XERO/BUDGET source pick, $ override, % adjust, and FROM/TO months. Blank rows at the bottom to add new expenses.
A9: XERO ACTUALS — expenses as booked, by vendor by month, with trend status (STEADY / GROWING / DROPPING / DROPPED / NEW / ONE-TIME / PERIODIC) and a suggested forward $/mo. Bottom block = actual P&L summary that PROJECTIONS reads.
A10: RAMP SCHEDULES — editable revenue ramp curves referenced by SALES TEAM.
A12: COLOR LEGEND
A13: BLUE text = yours to edit. YELLOW fill = master levers. Black = formulas (leave). GREEN = pulls from another tab. Dark gray = static data imported from Xero/the budget tool (refresh by re-running the build script).
A15: RULES & ASSUMPTIONS BAKED IN
... A26: Re-export the Xero GL Detail + the two CSVs, re-run the aggregation + tools/budgeting/build_budget_workbook.py in the repo, and a fresh workbook is produced. Your edits live in this file, so copy your blue cells forward (or ask Claude to merge).

Sheet PROJECTIONS
A1: PROJECTIONS — 2026 P&L: Xero actuals through the cutoff month, model after
A2: For leadership review. Columns up to the cutoff show Xero as booked; later columns are driven by STAFFING (payroll), SALES TEAM (revenue + variable comp, modest vs stretch), and EXPENSES (planned opex). Both scenarios display simultaneously. Yellow cells are the master levers.
A3: Actuals through month # | B3: 7 | C3: COGS % fwd | D3: 0.432 | E3: Other income $/mo fwd | F3: 3000 | G3: Labor hedge % fwd | H3: 0 | I3: Opex hedge % fwd | J3: 0 | K3: (Aug is partial in Xero — leave cutoff at 7 unless data refreshed)
B4: 1 | C4: 2 | D4: 3 | E4: 4 | F4: 5 | G4: 6 | H4: 7 | I4: 8 | J4: 9 | K4: 10 | L4: 11 | M4: 12
A5: 2026 | B5: Jan | C5: Feb | D5: Mar | E5: Apr | F5: May | G5: Jun | H5: Jul | I5: Aug | J5: Sep | K5: Oct | L5: Nov | M5: Dec | N5: FY 2026
B6: =IF(B$4<=$B$3,"ACTUAL","PROJ") -> ACTUAL | C6: =IF(C$4<=$B$3,"ACTUAL","PROJ") -> ACTUAL | D6: =IF(D$4<=$B$3,"ACTUAL","PROJ") -> ACTUAL | E6: =IF(E$4<=$B$3,"ACTUAL","PROJ") -> ACTUAL | F6: =IF(F$4<=$B$3,"ACTUAL","PROJ") -> ACTUAL | G6: =IF(G$4<=$B$3,"ACTUAL","PROJ") -> ACTUAL | H6: =IF(H$4<=$B$3,"ACTUAL","PROJ") -> ACTUAL | I6: =IF(I$4<=$B$3,"ACTUAL","PROJ") -> PROJ | ... M6: =IF(M$4<=$B$3,"ACTUAL","PROJ") -> PROJ
A8: REVENUE
A9: Sales revenue — MODEST | B9: =IF(B$4<=$B$3,'XERO ACTUALS'!B$137,'SALES TEAM'!I$26) -> 1040301.8 | C9: =IF(C$4<=$B$3,'XERO ACTUALS'!C$137,'SALES TEAM'!J$26) -> 962653.48 | D9: =IF(D$4<=$B$3,'XERO ACTUALS'!D$137,'SALES TEAM'!K$26) -> 807402.94 | E9: =IF(E$4<=$B$3,'XERO ACTUALS'!E$137,'SALES TEAM'!L$26) -> 1266520.8 | F9: =IF(F$4<=$B$3,'XERO ACTUALS'!F$137,'SALES TEAM'!M$26) -> 1375720.8 | G9: =IF(G$4<=$B$3,'XERO ACTUALS'!G$137,'SALES TEAM'!N$26) -> 1116661.8 | H9: =IF(H$4<=$B$3,'XERO ACTUALS'!H$137,'SALES TEAM'!O$26) -> 1363598.3 | I9: =IF(I$4<=$B$3,'XERO ACTUALS'!I$137,'SALES TEAM'!P$26) -> 1173201.6 | ... M9: =IF(M$4<=$B$3,'XERO ACTUALS'!M$137,'SALES TEAM'!T$26) -> 1250536 | N9: =SUM(B9:M9) -> 13956206
A10: Sales revenue — STRETCH | B10: =IF(B$4<=$B$3,'XERO ACTUALS'!B$137,'SALES TEAM'!I$27) -> 1040301.8 | C10: =IF(C$4<=$B$3,'XERO ACTUALS'!C$137,'SALES TEAM'!J$27) -> 962653.48 | D10: =IF(D$4<=$B$3,'XERO ACTUALS'!D$137,'SALES TEAM'!K$27) -> 807402.94 | E10: =IF(E$4<=$B$3,'XERO ACTUALS'!E$137,'SALES TEAM'!L$27) -> 1266520.8 | F10: =IF(F$4<=$B$3,'XERO ACTUALS'!F$137,'SALES TEAM'!M$27) -> 1375720.8 | G10: =IF(G$4<=$B$3,'XERO ACTUALS'!G$137,'SALES TEAM'!N$27) -> 1116661.8 | H10: =IF(H$4<=$B$3,'XERO ACTUALS'!H$137,'SALES TEAM'!O$27) -> 1363598.3 | I10: =IF(I$4<=$B$3,'XERO ACTUALS'!I$137,'SALES TEAM'!P$27) -> 1384002 | ... M10: =IF(M$4<=$B$3,'XERO ACTUALS'!M$137,'SALES TEAM'!T$27) -> 1480670 | N10: =SUM(B10:M10) -> 15049542
A11: Other income (rental, interest, rebates) | B11: =IF(B$4<=$B$3,'XERO ACTUALS'!B$138,$F$3) -> 129229.59 | C11: =IF(C$4<=$B$3,'XERO ACTUALS'!C$138,$F$3) -> 613.42 | D11: =IF(D$4<=$B$3,'XERO ACTUALS'!D$138,$F$3) -> 15629.36 | E11: =IF(E$4<=$B$3,'XERO ACTUALS'!E$138,$F$3) -> 1233.33 | F11: =IF(F$4<=$B$3,'XERO ACTUALS'!F$138,$F$3) -> 3051.67 | G11: =IF(G$4<=$B$3,'XERO ACTUALS'!G$138,$F$3) -> 3744.51 | H11: =IF(H$4<=$B$3,'XERO ACTUALS'!H$138,$F$3) -> 11390.34 | I11: =IF(I$4<=$B$3,'XERO ACTUALS'!I$138,$F$3) -> 3000 | ... M11: =IF(M$4<=$B$3,'XERO ACTUALS'!M$138,$F$3) -> 3000 | N11: =SUM(B11:M11) -> 179892.22
A12: TOTAL REVENUE — MODEST | B12: =B9+B11 -> 1169531.4 | C12: =C9+C11 -> 963266.9 | D12: =D9+D11 -> 823032.3 | E12: =E9+E11 -> 1267754.1 | F12: =F9+F11 -> 1378772.4 | G12: =G9+G11 -> 1120406.3 | H12: =H9+H11 -> 1374988.6 | I12: =I9+I11 -> 1176201.6 | ... M12: =M9+M11 -> 1253536 | N12: =SUM(B12:M12) -> 14136098
A13: TOTAL REVENUE — STRETCH | B13: =B10+B11 -> 1169531.4 | C13: =C10+C11 -> 963266.9 | D13: =D10+D11 -> 823032.3 | E13: =E10+E11 -> 1267754.1 | F13: =F10+F11 -> 1378772.4 | G13: =G10+G11 -> 1120406.3 | H13: =H10+H11 -> 1374988.6 | I13: =I10+I11 -> 1387002 | ... M13: =M10+M11 -> 1483670 | N13: =SUM(B13:M13) -> 15229434
A15: COST OF GOODS & INSTALL DELIVERY
A16: COGS % of sales revenue | B16: =IF(B$4<=$B$3,'XERO ACTUALS'!B$140,$D$3) -> 0.50827916 | C16: =IF(C$4<=$B$3,'XERO ACTUALS'!C$140,$D$3) -> 0.47260159 | D16: =IF(D$4<=$B$3,'XERO ACTUALS'!D$140,$D$3) -> 0.46386814 | E16: =IF(E$4<=$B$3,'XERO ACTUALS'!E$140,$D$3) -> 0.4958447 | F16: =IF(F$4<=$B$3,'XERO ACTUALS'!F$140,$D$3) -> 0.50527715 | G16: =IF(G$4<=$B$3,'XERO ACTUALS'!G$140,$D$3) -> 0.46093625 | H16: =IF(H$4<=$B$3,'XERO ACTUALS'!H$140,$D$3) -> 0.1703022 | I16: =IF(I$4<=$B$3,'XERO ACTUALS'!I$140,$D$3) -> 0.432 | ... M16: =IF(M$4<=$B$3,'XERO ACTUALS'!M$140,$D$3) -> 0.432 | N16: =IFERROR(N17/N9,0) -> 0.43209314
A17: COGS — MODEST | B17: =IF(B$4<=$B$3,'XERO ACTUALS'!B$139,B9*B16) -> 528763.75 | C17: =IF(C$4<=$B$3,'XERO ACTUALS'!C$139,C9*C16) -> 454951.57 | D17: =IF(D$4<=$B$3,'XERO ACTUALS'!D$139,D9*D16) -> 374528.5 | E17: =IF(E$4<=$B$3,'XERO ACTUALS'!E$139,E9*E16) -> 627997.63 | F17: =IF(F$4<=$B$3,'XERO ACTUALS'!F$139,F9*F16) -> 695120.27 | G17: =IF(G$4<=$B$3,'XERO ACTUALS'!G$139,G9*G16) -> 514709.89 | H17: =IF(H$4<=$B$3,'XERO ACTUALS'!H$139,H9*H16) -> 232223.79 | I17: =IF(I$4<=$B$3,'XERO ACTUALS'!I$139,I9*I16) -> 506823.09 | ... M17: =IF(M$4<=$B$3,'XERO ACTUALS'!M$139,M9*M16) -> 540231.55 | N17: =SUM(B17:M17) -> 6030380.7
A18: COGS — STRETCH | B18: =IF(B$4<=$B$3,'XERO ACTUALS'!B$139,B10*B16) -> 528763.75 | C18: =IF(C$4<=$B$3,'XERO ACTUALS'!C$139,C10*C16) -> 454951.57 | D18: =IF(D$4<=$B$3,'XERO ACTUALS'!D$139,D10*D16) -> 374528.5 | E18: =IF(E$4<=$B$3,'XERO ACTUALS'!E$139,E10*E16) -> 627997.63 | F18: =IF(F$4<=$B$3,'XERO ACTUALS'!F$139,F10*F16) -> 695120.27 | G18: =IF(G$4<=$B$3,'XERO ACTUALS'!G$139,G10*G16) -> 514709.89 | H18: =IF(H$4<=$B$3,'XERO ACTUALS'!H$139,H10*H16) -> 232223.79 | I18: =IF(I$4<=$B$3,'XERO ACTUALS'!I$139,I10*I16) -> 597888.86 | ... M18: =IF(M$4<=$B$3,'XERO ACTUALS'!M$139,M10*M16) -> 639649.44 | N18: =SUM(B18:M18) -> 6502702
A19: GROSS PROFIT — MODEST | B19: =B12-B17 -> 640767.68 | C19: =C12-C17 -> 508315.33 | D19: =D12-D17 -> 448503.8 | E19: =E12-E17 -> 639756.52 | F19: =F12-F17 -> 683652.18 | G19: =G12-G17 -> 605696.39 | H19: =H12-H17 -> 1142764.8 | I19: =I12-I17 -> 669378.51 | ... M19: =M12-M17 -> 713304.45 | N19: =SUM(B19:M19) -> 8105717
A20: GROSS PROFIT — STRETCH | B20: =B13-B18 -> 640767.68 | C20: =C13-C18 -> 508315.33 | D20: =D13-D18 -> 448503.8 | E20: =E13-E18 -> 639756.52 | F20: =F13-F18 -> 683652.18 | G20: =G13-G18 -> 605696.39 | H20: =H13-H18 -> 1142764.8 | I20: =I13-I18 -> 789113.14 | ... M20: =M13-M18 -> 844020.56 | N20: =SUM(B20:M20) -> 8726732.1
A22: PAYROLL & SALES COMP
A23: Payroll — staffing model (base + benefits + licenses) | B23: =IF(B$4<=$B$3,'XERO ACTUALS'!B$141,STAFFING!Z$47*(1+$H$3)) -> 340010.78 | C23: =IF(C$4<=$B$3,'XERO ACTUALS'!C$141,STAFFING!AA$47*(1+$H$3)) -> 306521.04 | D23: =IF(D$4<=$B$3,'XERO ACTUALS'!D$141,STAFFING!AB$47*(1+$H$3)) -> 338404.82 | E23: =IF(E$4<=$B$3,'XERO ACTUALS'!E$141,STAFFING!AC$47*(1+$H$3)) -> 356191.85 | F23: =IF(F$4<=$B$3,'XERO ACTUALS'!F$141,STAFFING!AD$47*(1+$H$3)) -> 302930.9 | G23: =IF(G$4<=$B$3,'XERO ACTUALS'!G$141,STAFFING!AE$47*(1+$H$3)) -> 232740.43 | H23: =IF(H$4<=$B$3,'XERO ACTUALS'!H$141,STAFFING!AF$47*(1+$H$3)) -> 285805.48 | I23: =IF(I$4<=$B$3,'XERO ACTUALS'!I$141,STAFFING!AG$47*(1+$H$3)) -> 326366.98 | ... M23: =IF(M$4<=$B$3,'XERO ACTUALS'!M$141,STAFFING!AK$47*(1+$H$3)) -> 326366.98 | N23: =SUM(B23:M23) -> 3794440.2
A24: Variable sales comp — MODEST (in booked payroll for actual months) | B24: =IF(B$4<=$B$3,0,'SALES TEAM'!I$34) -> 0 | C24: =IF(C$4<=$B$3,0,'SALES TEAM'!J$34) -> 0 | D24: =IF(D$4<=$B$3,0,'SALES TEAM'!K$34) -> 0 | E24: =IF(E$4<=$B$3,0,'SALES TEAM'!L$34) -> 0 | F24: =IF(F$4<=$B$3,0,'SALES TEAM'!M$34) -> 0 | G24: =IF(G$4<=$B$3,0,'SALES TEAM'!N$34) -> 0 | H24: =IF(H$4<=$B$3,0,'SALES TEAM'!O$34) -> 0 | I24: =IF(I$4<=$B$3,0,'SALES TEAM'!P$34) -> 46289.287 | ... M24: =IF(M$4<=$B$3,0,'SALES TEAM'!T$34) -> 52089.367 | N24: =SUM(B24:M24) -> 243246.75
A25: Variable sales comp — STRETCH (in booked payroll for actual months) | B25: =IF(B$4<=$B$3,0,'SALES TEAM'!I$35) -> 0 | C25: =IF(C$4<=$B$3,0,'SALES TEAM'!J$35) -> 0 | D25: =IF(D$4<=$B$3,0,'SALES TEAM'!K$35) -> 0 | E25: =IF(E$4<=$B$3,0,'SALES TEAM'!L$35) -> 0 | F25: =IF(F$4<=$B$3,0,'SALES TEAM'!M$35) -> 0 | G25: =IF(G$4<=$B$3,0,'SALES TEAM'!N$35) -> 0 | H25: =IF(H$4<=$B$3,0,'SALES TEAM'!O$35) -> 0 | I25: =IF(I$4<=$B$3,0,'SALES TEAM'!P$35) -> 61079.317 | ... M25: =IF(M$4<=$B$3,0,'SALES TEAM'!T$35) -> 68329.417 | N25: =SUM(B25:M25) -> 320146.98
A27: OPERATING EXPENSES (dept view — budgeting-tool allocations win)
A28: Sales | B28: =IF(B$4<=$B$3,'XERO ACTUALS'!B$142,EXPENSES!B$204*(1+$J$3)) -> 23880.9 | C28: =IF(C$4<=$B$3,'XERO ACTUALS'!C$142,EXPENSES!C$204*(1+$J$3)) -> 26194.9 | D28: =IF(D$4<=$B$3,'XERO ACTUALS'!D$142,EXPENSES!D$204*(1+$J$3)) -> 23702.9 | E28: =IF(E$4<=$B$3,'XERO ACTUALS'!E$142,EXPENSES!E$204*(1+$J$3)) -> 33135.62 | F28: =IF(F$4<=$B$3,'XERO ACTUALS'!F$142,EXPENSES!F$204*(1+$J$3)) -> 21940.07 | G28: =IF(G$4<=$B$3,'XERO ACTUALS'!G$142,EXPENSES!G$204*(1+$J$3)) -> 23914.68 | H28: =IF(H$4<=$B$3,'XERO ACTUALS'!H$142,EXPENSES!H$204*(1+$J$3)) -> 34292.15 | I28: =IF(I$4<=$B$3,'XERO ACTUALS'!I$142,EXPENSES!I$204*(1+$J$3)) -> 24880.618 | ... M28: =IF(M$4<=$B$3,'XERO ACTUALS'!M$142,EXPENSES!M$204*(1+$J$3)) -> 24880.618 | N28: =SUM(B28:M28) -> 311464.31
A29: Marketing | B29: =IF(B$4<=$B$3,'XERO ACTUALS'!B$143,EXPENSES!B$205*(1+$J$3)) -> 101112.98 | C29: =IF(C$4<=$B$3,'XERO ACTUALS'!C$143,EXPENSES!C$205*(1+$J$3)) -> 104346.54 | D29: =IF(D$4<=$B$3,'XERO ACTUALS'!D$143,EXPENSES!D$205*(1+$J$3)) -> 113683.94 | E29: =IF(E$4<=$B$3,'XERO ACTUALS'!E$143,EXPENSES!E$205*(1+$J$3)) -> 105145.29 | F29: =IF(F$4<=$B$3,'XERO ACTUALS'!F$143,EXPENSES!F$205*(1+$J$3)) -> 102201.14 | G29: =IF(G$4<=$B$3,'XERO ACTUALS'!G$143,EXPENSES!G$205*(1+$J$3)) -> 111565 | H29: =IF(H$4<=$B$3,'XERO ACTUALS'!H$143,EXPENSES!H$205*(1+$J$3)) -> 97344.03 | I29: =IF(I$4<=$B$3,'XERO ACTUALS'!I$143,EXPENSES!I$205*(1+$J$3)) -> 101984.67 | ... M29: =IF(M$4<=$B$3,'XERO ACTUALS'!M$143,EXPENSES!M$205*(1+$J$3)) -> 101984.67 | N29: =SUM(B29:M29) -> 1245322.3
A30: Software Development | B30: =IF(B$4<=$B$3,'XERO ACTUALS'!B$144,EXPENSES!B$206*(1+$J$3)) -> 15329.12 | C30: =IF(C$4<=$B$3,'XERO ACTUALS'!C$144,EXPENSES!C$206*(1+$J$3)) -> 18543.25 | D30: =IF(D$4<=$B$3,'XERO ACTUALS'!D$144,EXPENSES!D$206*(1+$J$3)) -> 14275.73 | E30: =IF(E$4<=$B$3,'XERO ACTUALS'!E$144,EXPENSES!E$206*(1+$J$3)) -> 15372.76 | F30: =IF(F$4<=$B$3,'XERO ACTUALS'!F$144,EXPENSES!F$206*(1+$J$3)) -> 15712.7 | G30: =IF(G$4<=$B$3,'XERO ACTUALS'!G$144,EXPENSES!G$206*(1+$J$3)) -> 15725.04 | H30: =IF(H$4<=$B$3,'XERO ACTUALS'!H$144,EXPENSES!H$206*(1+$J$3)) -> 15218.69 | I30: =IF(I$4<=$B$3,'XERO ACTUALS'!I$144,EXPENSES!I$206*(1+$J$3)) -> 16555.143 | ... M30: =IF(M$4<=$B$3,'XERO ACTUALS'!M$144,EXPENSES!M$206*(1+$J$3)) -> 16555.143 | N30: =SUM(B30:M30) -> 192953.01
A31: Installation Services | B31: =IF(B$4<=$B$3,'XERO ACTUALS'!B$145,EXPENSES!B$207*(1+$J$3)) -> 1317.66 | C31: =IF(C$4<=$B$3,'XERO ACTUALS'!C$145,EXPENSES!C$207*(1+$J$3)) -> 752.62 | D31: =IF(D$4<=$B$3,'XERO ACTUALS'!D$145,EXPENSES!D$207*(1+$J$3)) -> 922.49 | E31: =IF(E$4<=$B$3,'XERO ACTUALS'!E$145,EXPENSES!E$207*(1+$J$3)) -> 921.14 | F31: =IF(F$4<=$B$3,'XERO ACTUALS'!F$145,EXPENSES!F$207*(1+$J$3)) -> 830.47 | G31: =IF(G$4<=$B$3,'XERO ACTUALS'!G$145,EXPENSES!G$207*(1+$J$3)) -> 892.67 | H31: =IF(H$4<=$B$3,'XERO ACTUALS'!H$145,EXPENSES!H$207*(1+$J$3)) -> 796.3 | I31: =IF(I$4<=$B$3,'XERO ACTUALS'!I$145,EXPENSES!I$207*(1+$J$3)) -> 2086.6659 | ... M31: =IF(M$4<=$B$3,'XERO ACTUALS'!M$145,EXPENSES!M$207*(1+$J$3)) -> 2086.6659 | N31: =SUM(B31:M31) -> 16866.68
A32: Technical Support | B32: =IF(B$4<=$B$3,'XERO ACTUALS'!B$146,EXPENSES!B$208*(1+$J$3)) -> 319 | C32: =IF(C$4<=$B$3,'XERO ACTUALS'!C$146,EXPENSES!C$208*(1+$J$3)) -> 319 | D32: =IF(D$4<=$B$3,'XERO ACTUALS'!D$146,EXPENSES!D$208*(1+$J$3)) -> 319 | E32: =IF(E$4<=$B$3,'XERO ACTUALS'!E$146,EXPENSES!E$208*(1+$J$3)) -> 341.33 | F32: =IF(F$4<=$B$3,'XERO ACTUALS'!F$146,EXPENSES!F$208*(1+$J$3)) -> 341.33 | G32: =IF(G$4<=$B$3,'XERO ACTUALS'!G$146,EXPENSES!G$208*(1+$J$3)) -> 341.33 | H32: =IF(H$4<=$B$3,'XERO ACTUALS'!H$146,EXPENSES!H$208*(1+$J$3)) -> 341.33 | I32: =IF(I$4<=$B$3,'XERO ACTUALS'!I$146,EXPENSES!I$208*(1+$J$3)) -> 372.31212 | ... M32: =IF(M$4<=$B$3,'XERO ACTUALS'!M$146,EXPENSES!M$208*(1+$J$3)) -> 372.31212 | N32: =SUM(B32:M32) -> 4183.8806
A33: Purchasing & Fulfillment | B33: =IF(B$4<=$B$3,'XERO ACTUALS'!B$147,EXPENSES!B$209*(1+$J$3)) -> 1043 | C33: =IF(C$4<=$B$3,'XERO ACTUALS'!C$147,EXPENSES!C$209*(1+$J$3)) -> 1043 | D33: =IF(D$4<=$B$3,'XERO ACTUALS'!D$147,EXPENSES!D$209*(1+$J$3)) -> 1043 | E33: =IF(E$4<=$B$3,'XERO ACTUALS'!E$147,EXPENSES!E$209*(1+$J$3)) -> 1043 | F33: =IF(F$4<=$B$3,'XERO ACTUALS'!F$147,EXPENSES!F$209*(1+$J$3)) -> 1043 | G33: =IF(G$4<=$B$3,'XERO ACTUALS'!G$147,EXPENSES!G$209*(1+$J$3)) -> 1043 | H33: =IF(H$4<=$B$3,'XERO ACTUALS'!H$147,EXPENSES!H$209*(1+$J$3)) -> 1043 | I33: =IF(I$4<=$B$3,'XERO ACTUALS'!I$147,EXPENSES!I$209*(1+$J$3)) -> 1043 | ... M33: =IF(M$4<=$B$3,'XERO ACTUALS'!M$147,EXPENSES!M$209*(1+$J$3)) -> 1043 | N33: =SUM(B33:M33) -> 12516
A34: 03 - HR & Business Administration Manager | B34: =IF(B$4<=$B$3,'XERO ACTUALS'!B$148,EXPENSES!B$210*(1+$J$3)) -> 14365.42 | C34: =IF(C$4<=$B$3,'XERO ACTUALS'!C$148,EXPENSES!C$210*(1+$J$3)) -> 10285.7 | D34: =IF(D$4<=$B$3,'XERO ACTUALS'!D$148,EXPENSES!D$210*(1+$J$3)) -> 14282.72 | E34: =IF(E$4<=$B$3,'XERO ACTUALS'!E$148,EXPENSES!E$210*(1+$J$3)) -> 16199.33 | F34: =IF(F$4<=$B$3,'XERO ACTUALS'!F$148,EXPENSES!F$210*(1+$J$3)) -> 5398.56 | G34: =IF(G$4<=$B$3,'XERO ACTUALS'!G$148,EXPENSES!G$210*(1+$J$3)) -> 8066.8 | H34: =IF(H$4<=$B$3,'XERO ACTUALS'!H$148,EXPENSES!H$210*(1+$J$3)) -> 6304.26 | I34: =IF(I$4<=$B$3,'XERO ACTUALS'!I$148,EXPENSES!I$210*(1+$J$3)) -> 5812.718 | ... M34: =IF(M$4<=$B$3,'XERO ACTUALS'!M$148,EXPENSES!M$210*(1+$J$3)) -> 5812.718 | N34: =SUM(B34:M34) -> 103966.38
A35: Facillities | B35: =IF(B$4<=$B$3,'XERO ACTUALS'!B$149,EXPENSES!B$211*(1+$J$3)) -> 15328.39 | C35: =IF(C$4<=$B$3,'XERO ACTUALS'!C$149,EXPENSES!C$211*(1+$J$3)) -> 14036.16 | D35: =IF(D$4<=$B$3,'XERO ACTUALS'!D$149,EXPENSES!D$211*(1+$J$3)) -> 15051.56 | E35: =IF(E$4<=$B$3,'XERO ACTUALS'!E$149,EXPENSES!E$211*(1+$J$3)) -> 16688.63 | F35: =IF(F$4<=$B$3,'XERO ACTUALS'!F$149,EXPENSES!F$211*(1+$J$3)) -> 27807.18 | G35: =IF(G$4<=$B$3,'XERO ACTUALS'!G$149,EXPENSES!G$211*(1+$J$3)) -> 14012.26 | H35: =IF(H$4<=$B$3,'XERO ACTUALS'!H$149,EXPENSES!H$211*(1+$J$3)) -> 14283.72 | I35: =IF(I$4<=$B$3,'XERO ACTUALS'!I$149,EXPENSES!I$211*(1+$J$3)) -> 16759.561 | ... M35: =IF(M$4<=$B$3,'XERO ACTUALS'!M$149,EXPENSES!M$211*(1+$J$3)) -> 16759.561 | N35: =SUM(B35:M35) -> 201005.71
A36: Exec | B36: =IF(B$4<=$B$3,'XERO ACTUALS'!B$150,EXPENSES!B$212*(1+$J$3)) -> 0 | C36: =IF(C$4<=$B$3,'XERO ACTUALS'!C$150,EXPENSES!C$212*(1+$J$3)) -> 0 | D36: =IF(D$4<=$B$3,'XERO ACTUALS'!D$150,EXPENSES!D$212*(1+$J$3)) -> 0 | E36: =IF(E$4<=$B$3,'XERO ACTUALS'!E$150,EXPENSES!E$212*(1+$J$3)) -> 0 | F36: =IF(F$4<=$B$3,'XERO ACTUALS'!F$150,EXPENSES!F$212*(1+$J$3)) -> 0 | G36: =IF(G$4<=$B$3,'XERO ACTUALS'!G$150,EXPENSES!G$212*(1+$J$3)) -> 1407.43 | H36: =IF(H$4<=$B$3,'XERO ACTUALS'!H$150,EXPENSES!H$212*(1+$J$3)) -> 56.37 | I36: =IF(I$4<=$B$3,'XERO ACTUALS'!I$150,EXPENSES!I$212*(1+$J$3)) -> 884.34691 | ... M36: =IF(M$4<=$B$3,'XERO ACTUALS'!M$150,EXPENSES!M$212*(1+$J$3)) -> 884.34691 | N36: =SUM(B36:M36) -> 5885.5346
A37: Product | B37: =IF(B$4<=$B$3,'XERO ACTUALS'!B$151,EXPENSES!B$213*(1+$J$3)) -> 0 | C37: =IF(C$4<=$B$3,'XERO ACTUALS'!C$151,EXPENSES!C$213*(1+$J$3)) -> 0 | D37: =IF(D$4<=$B$3,'XERO ACTUALS'!D$151,EXPENSES!D$213*(1+$J$3)) -> 0 | E37: =IF(E$4<=$B$3,'XERO ACTUALS'!E$151,EXPENSES!E$213*(1+$J$3)) -> 0 | F37: =IF(F$4<=$B$3,'XERO ACTUALS'!F$151,EXPENSES!F$213*(1+$J$3)) -> 0 | G37: =IF(G$4<=$B$3,'XERO ACTUALS'!G$151,EXPENSES!G$213*(1+$J$3)) -> 0 | H37: =IF(H$4<=$B$3,'XERO ACTUALS'!H$151,EXPENSES!H$213*(1+$J$3)) -> 0 | I37: =IF(I$4<=$B$3,'XERO ACTUALS'!I$151,EXPENSES!I$213*(1+$J$3)) -> 0 | ... M37: =IF(M$4<=$B$3,'XERO ACTUALS'!M$151,EXPENSES!M$213*(1+$J$3)) -> 0 | N37: =SUM(B37:M37) -> 0
A38: General Overhead | B38: =IF(B$4<=$B$3,'XERO ACTUALS'!B$152,EXPENSES!B$214*(1+$J$3)) -> 3409 | C38: =IF(C$4<=$B$3,'XERO ACTUALS'!C$152,EXPENSES!C$214*(1+$J$3)) -> 3978.92 | D38: =IF(D$4<=$B$3,'XERO ACTUALS'!D$152,EXPENSES!D$214*(1+$J$3)) -> 3910 | E38: =IF(E$4<=$B$3,'XERO ACTUALS'!E$152,EXPENSES!E$214*(1+$J$3)) -> 4244 | F38: =IF(F$4<=$B$3,'XERO ACTUALS'!F$152,EXPENSES!F$214*(1+$J$3)) -> 4173.75 | G38: =IF(G$4<=$B$3,'XERO ACTUALS'!G$152,EXPENSES!G$214*(1+$J$3)) -> 4028.6 | H38: =IF(H$4<=$B$3,'XERO ACTUALS'!H$152,EXPENSES!H$214*(1+$J$3)) -> 4126 | I38: =IF(I$4<=$B$3,'XERO ACTUALS'!I$152,EXPENSES!I$214*(1+$J$3)) -> 2754.992 | ... M38: =IF(M$4<=$B$3,'XERO ACTUALS'!M$152,EXPENSES!M$214*(1+$J$3)) -> 2754.992 | N38: =SUM(B38:M38) -> 41645.23
A39: Unassigned | B39: =IF(B$4<=$B$3,'XERO ACTUALS'!B$153,EXPENSES!B$215*(1+$J$3)) -> 20046.46 | C39: =IF(C$4<=$B$3,'XERO ACTUALS'!C$153,EXPENSES!C$215*(1+$J$3)) -> 21603.25 | D39: =IF(D$4<=$B$3,'XERO ACTUALS'!D$153,EXPENSES!D$215*(1+$J$3)) -> 49688.47 | E39: =IF(E$4<=$B$3,'XERO ACTUALS'!E$153,EXPENSES!E$215*(1+$J$3)) -> 24996.78 | F39: =IF(F$4<=$B$3,'XERO ACTUALS'!F$153,EXPENSES!F$215*(1+$J$3)) -> 19300.85 | G39: =IF(G$4<=$B$3,'XERO ACTUALS'!G$153,EXPENSES!G$215*(1+$J$3)) -> 26848.19 | H39: =IF(H$4<=$B$3,'XERO ACTUALS'!H$153,EXPENSES!H$215*(1+$J$3)) -> 26078.03 | I39: =IF(I$4<=$B$3,'XERO ACTUALS'!I$153,EXPENSES!I$215*(1+$J$3)) -> 23294.033 | ... M39: =IF(M$4<=$B$3,'XERO ACTUALS'!M$153,EXPENSES!M$215*(1+$J$3)) -> 23294.033 | N39: =SUM(B39:M39) -> 305032.2
A40: TOTAL OPERATING EXPENSES | B40: =SUM(B28:B39) -> 196151.93 | C40: =SUM(C28:C39) -> 201103.34 | D40: =SUM(D28:D39) -> 236879.81 | E40: =SUM(E28:E39) -> 218087.88 | F40: =SUM(F28:F39) -> 198749.05 | G40: =SUM(G28:G39) -> 207845 | H40: =SUM(H28:H39) -> 199883.88 | I40: =SUM(I28:I39) -> 196428.06 | ... M40: =SUM(M28:M39) -> 196428.06 | N40: =SUM(B40:M40) -> 2440841.2
A42: BOTTOM LINE
A43: NET PROFIT — MODEST | B43: =B19-B23-B24-B40 -> 104604.97 | C43: =C19-C23-C24-C40 -> 690.95 | D43: =D19-D23-D24-D40 -> -126780.83 | E43: =E19-E23-E24-E40 -> 65476.79 | F43: =F19-F23-F24-F40 -> 181972.23 | G43: =G19-G23-G24-G40 -> 165110.96 | H43: =H19-H23-H24-H40 -> 657075.48 | I43: =I19-I23-I24-I40 -> 100294.18 | ... M43: =M19-M23-M24-M40 -> 138420.04 | N43: =SUM(B43:M43) -> 1627188.9
A44: NET PROFIT — STRETCH | B44: =B20-B23-B25-B40 -> 104604.97 | C44: =C20-C23-C25-C40 -> 690.95 | D44: =D20-D23-D25-D40 -> -126780.83 | E44: =E20-E23-E25-E40 -> 65476.79 | F44: =F20-F23-F25-F40 -> 181972.23 | G44: =G20-G23-G25-G40 -> 165110.96 | H44: =H20-H23-H25-H40 -> 657075.48 | I44: =I20-I23-I25-I40 -> 205238.77 | ... M44: =M20-M23-M25-M40 -> 252896.1 | N44: =SUM(B44:M44) -> 2171303.7
A45: Net margin — modest | B45: =IFERROR(B43/B12,0) -> 0.089441778 | C45: =IFERROR(C43/C12,0) -> 0.0007172986 | D45: =IFERROR(D43/D12,0) -> -0.15404114 | E45: =IFERROR(E43/E12,0) -> 0.051647861 | F45: =IFERROR(F43/F12,0) -> 0.13198134 | G45: =IFERROR(G43/G12,0) -> 0.14736704 | H45: =IFERROR(H43/H12,0) -> 0.47787703 | I45: =IFERROR(I43/I12,0) -> 0.085269546 | ... N45: =IFERROR(N43/N12,0) -> 0.11510877
...

Sheet SALES TEAM
A1: SALES TEAM — individual reps, ramps, MODEST vs STRETCH attainment, and comp liability
A2: Blue = editable. Each rep: pick a ramp curve, a start month (may be ≤ 0 if they started before 2026), then set attainment per scenario — e.g. Zach 80% modest / 100% stretch. Monthly revenue = ramp value for their tenure month × attainment. COMM % is paid on attained revenue (defaults from the legacy tool: AE 2.5%, AM 1.5%, Sr AE 1.75% — edit freely). Sales Manager + Director overrides are computed below the table. Base salaries live on STAFFING.
A3: Annual revenue target ($) | B3: 12050000 | D3: SM override % (of all sales) | E3: 0.015 | G3: Director override % (above target) | H3: 0.035 | J3: Monthly target | K3: =$B$3/12 -> 1004166.7
I4: 1 | J4: 2 | K4: 3 | L4: 4 | M4: 5 | N4: 6 | O4: 7 | P4: 8 | Q4: 9 | R4: 10 | S4: 11 | T4: 12 | U4: 1 | V4: 2 | W4: 3 | X4: 4 | Y4: 5 | Z4: 6 | AA4: 7 | AB4: 8 | AC4: 9 | AD4: 10 | AE4: 11 | AF4: 12
A5: REP / SOURCE | B5: ROLE | C5: RAMP CURVE | D5: START MO (≤0 = pre-2026) | E5: MODEST % | F5: STRETCH % | G5: COMM % | H5: FY RUN-RATE QUOTA | I5: MOD Jan | J5: MOD Feb | K5: MOD Mar | L5: MOD Apr | M5: MOD May | N5: MOD Jun | O5: MOD Jul | P5: MOD Aug | Q5: MOD Sep | R5: MOD Oct | S5: MOD Nov | T5: MOD Dec | U5: STR Jan | V5: STR Feb | W5: STR Mar | X5: STR Apr | Y5: STR May | Z5: STR Jun | AA5: STR Jul | AB5: STR Aug | AC5: STR Sep | AD5: STR Oct | AE5: STR Nov | AF5: STR Dec | AG5: FY MODEST | AH5: FY STRETCH | AI5: FY COMM MOD | AJ5: FY COMM STR
A6: Senior Account Executive - Stu Moore | B6: Senior Account Executive - Stu Moore | C6: STU | D6: -8 | E6: 1 | F6: 1 | G6: 0.0175 | H6: =IF($C6="",0,12*INDEX('RAMP SCHEDULES'!$B$4:$M$13,MATCH($C6,'RAMP SCHEDULES'!$A$4:$A$13,0),12)) -> 3960000 | I6: =IF(OR($C6="",I$4<$D6),0,INDEX('RAMP SCHEDULES'!$B$4:$M$13,MATCH($C6,'RAMP SCHEDULES'!$A$4:$A$13,0),MIN(12,I$4-$D6+1))*$E6) -> 330000 | J6: =IF(OR($C6="",J$4<$D6),0,INDEX('RAMP SCHEDULES'!$B$4:$M$13,MATCH($C6,'RAMP SCHEDULES'!$A$4:$A$13,0),MIN(12,J$4-$D6+1))*$E6) -> 330000 | K6: =IF(OR($C6="",K$4<$D6),0,INDEX('RAMP SCHEDULES'!$B$4:$M$13,MATCH($C6,'RAMP SCHEDULES'!$A$4:$A$13,0),MIN(12,K$4-$D6+1))*$E6) -> 330000 | L6: =IF(OR($C6="",L$4<$D6),0,INDEX('RAMP SCHEDULES'!$B$4:$M$13,MATCH($C6,'RAMP SCHEDULES'!$A$4:$A$13,0),MIN(12,L$4-$D6+1))*$E6) -> 330000 | M6: =IF(OR($C6="",M$4<$D6),0,INDEX('RAMP SCHEDULES'!$B$4:$M$13,MATCH($C6,'RAMP SCHEDULES'!$A$4:$A$13,0),MIN(12,M$4-$D6+1))*$E6) -> 330000 | N6: =IF(OR($C6="",N$4<$D6),0,INDEX('RAMP SCHEDULES'!$B$4:$M$13,MATCH($C6,'RAMP SCHEDULES'!$A$4:$A$13,0),MIN(12,N$4-$D6+1))*$E6) -> 330000 | O6: =IF(OR($C6="",O$4<$D6),0,INDEX('RAMP SCHEDULES'!$B$4:$M$13,MATCH($C6,'RAMP SCHEDULES'!$A$4:$A$13,0),MIN(12,O$4-$D6+1))*$E6) -> 330000 | P6: =IF(OR($C6="",P$4<$D6),0,INDEX('RAMP SCHEDULES'!$B$4:$M$13,MATCH($C6,'RAMP SCHEDULES'!$A$4:$A$13,0),MIN(12,P$4-$D6+1))*$E6) -> 330000 | ... T6: =IF(OR($C6="",T$4<$D6),0,INDEX('RAMP SCHEDULES'!$B$4:$M$13,MATCH($C6,'RAMP SCHEDULES'!$A$4:$A$13,0),MIN(12,T$4-$D6+1))*$E6) -> 330000 | U6: =IF(OR($C6="",U$4<$D6),0,INDEX('RAMP SCHEDULES'!$B$4:$M$13,MATCH($C6,'RAMP SCHEDULES'!$A$4:$A$13,0),MIN(12,U$4-$D6+1))*$F6) -> 330000 | V6: =IF(OR($C6="",V$4<$D6),0,INDEX('RAMP SCHEDULES'!$B$4:$M$13,MATCH($C6,'RAMP SCHEDULES'!$A$4:$A$13,0),MIN(12,V$4-$D6+1))*$F6) -> 330000 | W6: =IF(OR($C6="",W$4<$D6),0,INDEX('RAMP SCHEDULES'!$B$4:$M$13,MATCH($C6,'RAMP SCHEDULES'!$A$4:$A$13,0),MIN(12,W$4-$D6+1))*$F6) -> 330000 | X6: =IF(OR($C6="",X$4<$D6),0,INDEX('RAMP SCHEDULES'!$B$4:$M$13,MATCH($C6,'RAMP SCHEDULES'!$A$4:$A$13,0),MIN(12,X$4-$D6+1))*$F6) -> 330000 | Y6: =IF(OR($C6="",Y$4<$D6),0,INDEX('RAMP SCHEDULES'!$B$4:$M$13,MATCH($C6,'RAMP SCHEDULES'!$A$4:$A$13,0),MIN(12,Y$4-$D6+1))*$F6) -> 330000 | Z6: =IF(OR($C6="",Z$4<$D6),0,INDEX('RAMP SCHEDULES'!$B$4:$M$13,MATCH($C6,'RAMP SCHEDULES'!$A$4:$A$13,0),MIN(12,Z$4-$D6+1))*$F6) -> 330000 | AA6: =IF(OR($C6="",AA$4<$D6),0,INDEX('RAMP SCHEDULES'!$B$4:$M$13,MATCH($C6,'RAMP SCHEDULES'!$A$4:$A$13,0),MIN(12,AA$4-$D6+1))*$F6) -> 330000 | AB6: =IF(OR($C6="",AB$4<$D6),0,INDEX('RAMP SCHEDULES'!$B$4:$M$13,MATCH($C6,'RAMP SCHEDULES'!$A$4:$A$13,0),MIN(12,AB$4-$D6+1))*$F6) -> 330000 | ... AF6: =IF(OR($C6="",AF$4<$D6),0,INDEX('RAMP SCHEDULES'!$B$4:$M$13,MATCH($C6,'RAMP SCHEDULES'!$A$4:$A$13,0),MIN(12,AF$4-$D6+1))*$F6) -> 330000 | AG6: =SUM(I6:T6) -> 3960000 | AH6: =SUM(U6:AF6) -> 3960000 | AI6: =AG6*$G6 -> 69300 | AJ6: =AH6*$G6 -> 69300
A7: Danny Mize | B7: Account Executive - RAMP | C7: AM -> AE | D7: -8 | E7: 0.8 | F7: 1 | G7: 0.025 | H7: =IF($C7="",0,12*INDEX('RAMP SCHEDULES'!$B$4:$M$13,MATCH($C7,'RAMP SCHEDULES'!$A$4:$A$13,0),12)) -> 1000008 | I7: =IF(OR($C7="",I$4<$D7),0,INDEX('RAMP SCHEDULES'!$B$4:$M$13,MATCH($C7,'RAMP SCHEDULES'!$A$4:$A$13,0),MIN(12,I$4-$D7+1))*$E7) -> 66666.4 | J7: =IF(OR($C7="",J$4<$D7),0,INDEX('RAMP SCHEDULES'!$B$4:$M$13,MATCH($C7,'RAMP SCHEDULES'!$A$4:$A$13,0),MIN(12,J$4-$D7+1))*$E7) -> 66666.4 | K7: =IF(OR($C7="",K$4<$D7),0,INDEX('RAMP SCHEDULES'!$B$4:$M$13,MATCH($C7,'RAMP SCHEDULES'!$A$4:$A$13,0),MIN(12,K$4-$D7+1))*$E7) -> 66667.2 | L7: =IF(OR($C7="",L$4<$D7),0,INDEX('RAMP SCHEDULES'!$B$4:$M$13,MATCH($C7,'RAMP SCHEDULES'!$A$4:$A$13,0),MIN(12,L$4-$D7+1))*$E7) -> 66667.2 | M7: =IF(OR($C7="",M$4<$D7),0,INDEX('RAMP SCHEDULES'!$B$4:$M$13,MATCH($C7,'RAMP SCHEDULES'!$A$4:$A$13,0),MIN(12,M$4-$D7+1))*$E7) -> 66667.2 | N7: =IF(OR($C7="",N$4<$D7),0,INDEX('RAMP SCHEDULES'!$B$4:$M$13,MATCH($C7,'RAMP SCHEDULES'!$A$4:$A$13,0),MIN(12,N$4-$D7+1))*$E7) -> 66667.2 | O7: =IF(OR($C7="",O$4<$D7),0,INDEX('RAMP SCHEDULES'!$B$4:$M$13,MATCH($C7,'RAMP SCHEDULES'!$A$4:$A$13,0),MIN(12,O$4-$D7+1))*$E7) -> 66667.2 | P7: =IF(OR($C7="",P$4<$D7),0,INDEX('RAMP SCHEDULES'!$B$4:$M$13,MATCH($C7,'RAMP SCHEDULES'!$A$4:$A$13,0),MIN(12,P$4-$D7+1))*$E7) -> 66667.2 | ... T7: =IF(OR($C7="",T$4<$D7),0,INDEX('RAMP SCHEDULES'!$B$4:$M$13,MATCH($C7,'RAMP SCHEDULES'!$A$4:$A$13,0),MIN(12,T$4-$D7+1))*$E7) -> 66667.2 | U7: =IF(OR($C7="",U$4<$D7),0,INDEX('RAMP SCHEDULES'!$B$4:$M$13,MATCH($C7,'RAMP SCHEDULES'!$A$4:$A$13,0),MIN(12,U$4-$D7+1))*$F7) -> 83333 | V7: =IF(OR($C7="",V$4<$D7),0,INDEX('RAMP SCHEDULES'!$B$4:$M$13,MATCH($C7,'RAMP SCHEDULES'!$A$4:$A$13,0),MIN(12,V$4-$D7+1))*$F7) -> 83333 | W7: =IF(OR($C7="",W$4<$D7),0,INDEX('RAMP SCHEDULES'!$B$4:$M$13,MATCH($C7,'RAMP SCHEDULES'!$A$4:$A$13,0),MIN(12,W$4-$D7+1))*$F7) -> 83334 | X7: =IF(OR($C7="",X$4<$D7),0,INDEX('RAMP SCHEDULES'!$B$4:$M$13,MATCH($C7,'RAMP SCHEDULES'!$A$4:$A$13,0),MIN(12,X$4-$D7+1))*$F7) -> 83334 | Y7: =IF(OR($C7="",Y$4<$D7),0,INDEX('RAMP SCHEDULES'!$B$4:$M$13,MATCH($C7,'RAMP SCHEDULES'!$A$4:$A$13,0),MIN(12,Y$4-$D7+1))*$F7) -> 83334 | Z7: =IF(OR($C7="",Z$4<$D7),0,INDEX('RAMP SCHEDULES'!$B$4:$M$13,MATCH($C7,'RAMP SCHEDULES'!$A$4:$A$13,0),MIN(12,Z$4-$D7+1))*$F7) -> 83334 | AA7: =IF(OR($C7="",AA$4<$D7),0,INDEX('RAMP SCHEDULES'!$B$4:$M$13,MATCH($C7,'RAMP SCHEDULES'!$A$4:$A$13,0),MIN(12,AA$4-$D7+1))*$F7) -> 83334 | AB7: =IF(OR($C7="",AB$4<$D7),0,INDEX('RAMP SCHEDULES'!$B$4:$M$13,MATCH($C7,'RAMP SCHEDULES'!$A$4:$A$13,0),MIN(12,AB$4-$D7+1))*$F7) -> 83334 | ... AF7: =IF(OR($C7="",AF$4<$D7),0,INDEX('RAMP SCHEDULES'!$B$4:$M$13,MATCH($C7,'RAMP SCHEDULES'!$A$4:$A$13,0),MIN(12,AF$4-$D7+1))*$F7) -> 83334 | AG7: =SUM(I7:T7) -> 800004.8 | AH7: =SUM(U7:AF7) -> 1000006 | AI7: =AG7*$G7 -> 20000.12 | AJ7: =AH7*$G7 -> 25000.15
A8: Sam Childers | B8: Account Executive - RAMP | C8: NEW AE | D8: -8 | E8: 0.8 | F8: 1 | G8: 0.025 | H8: =IF($C8="",0,12*INDEX('RAMP SCHEDULES'!$B$4:$M$13,MATCH($C8,'RAMP SCHEDULES'!$A$4:$A$13,0),12)) -> 1000008 | I8: =IF(OR($C8="",I$4<$D8),0,INDEX('RAMP SCHEDULES'!$B$4:$M$13,MATCH($C8,'RAMP SCHEDULES'!$A$4:$A$13,0),MIN(12,I$4-$D8+1))*$E8) -> 66666.4 | J8: =IF(OR($C8="",J$4<$D8),0,INDEX('RAMP SCHEDULES'!$B$4:$M$13,MATCH($C8,'RAMP SCHEDULES'!$A$4:$A$13,0),MIN(12,J$4-$D8+1))*$E8) -> 66666.4 | K8: =IF(OR($C8="",K$4<$D8),0,INDEX('RAMP SCHEDULES'!$B$4:$M$13,MATCH($C8,'RAMP SCHEDULES'!$A$4:$A$13,0),MIN(12,K$4-$D8+1))*$E8) -> 66667.2 | L8: =IF(OR($C8="",L$4<$D8),0,INDEX('RAMP SCHEDULES'!$B$4:$M$13,MATCH($C8,'RAMP SCHEDULES'!$A$4:$A$13,0),MIN(12,L$4-$D8+1))*$E8) -> 66667.2 | M8: =IF(OR($C8="",M$4<$D8),0,INDEX('RAMP SCHEDULES'!$B$4:$M$13,MATCH($C8,'RAMP SCHEDULES'!$A$4:$A$13,0),MIN(12,M$4-$D8+1))*$E8) -> 66667.2 | N8: =IF(OR($C8="",N$4<$D8),0,INDEX('RAMP SCHEDULES'!$B$4:$M$13,MATCH($C8,'RAMP SCHEDULES'!$A$4:$A$13,0),MIN(12,N$4-$D8+1))*$E8) -> 66667.2 | O8: =IF(OR($C8="",O$4<$D8),0,INDEX('RAMP SCHEDULES'!$B$4:$M$13,MATCH($C8,'RAMP SCHEDULES'!$A$4:$A$13,0),MIN(12,O$4-$D8+1))*$E8) -> 66667.2 | P8: =IF(OR($C8="",P$4<$D8),0,INDEX('RAMP SCHEDULES'!$B$4:$M$13,MATCH($C8,'RAMP SCHEDULES'!$A$4:$A$13,0),MIN(12,P$4-$D8+1))*$E8) -> 66667.2 | ... T8: =IF(OR($C8="",T$4<$D8),0,INDEX('RAMP SCHEDULES'!$B$4:$M$13,MATCH($C8,'RAMP SCHEDULES'!$A$4:$A$13,0),MIN(12,T$4-$D8+1))*$E8) -> 66667.2 | U8: =IF(OR($C8="",U$4<$D8),0,INDEX('RAMP SCHEDULES'!$B$4:$M$13,MATCH($C8,'RAMP SCHEDULES'!$A$4:$A$13,0),MIN(12,U$4-$D8+1))*$F8) -> 83333 | V8: =IF(OR($C8="",V$4<$D8),0,INDEX('RAMP SCHEDULES'!$B$4:$M$13,MATCH($C8,'RAMP SCHEDULES'!$A$4:$A$13,0),MIN(12,V$4-$D8+1))*$F8) -> 83333 | W8: =IF(OR($C8="",W$4<$D8),0,INDEX('RAMP SCHEDULES'!$B$4:$M$13,MATCH($C8,'RAMP SCHEDULES'!$A$4:$A$13,0),MIN(12,W$4-$D8+1))*$F8) -> 83334 | X8: =IF(OR($C8="",X$4<$D8),0,INDEX('RAMP SCHEDULES'!$B$4:$M$13,MATCH($C8,'RAMP SCHEDULES'!$A$4:$A$13,0),MIN(12,X$4-$D8+1))*$F8) -> 83334 | Y8: =IF(OR($C8="",Y$4<$D8),0,INDEX('RAMP SCHEDULES'!$B$4:$M$13,MATCH($C8,'RAMP SCHEDULES'!$A$4:$A$13,0),MIN(12,Y$4-$D8+1))*$F8) -> 83334 | Z8: =IF(OR($C8="",Z$4<$D8),0,INDEX('RAMP SCHEDULES'!$B$4:$M$13,MATCH($C8,'RAMP SCHEDULES'!$A$4:$A$13,0),MIN(12,Z$4-$D8+1))*$F8) -> 83334 | AA8: =IF(OR($C8="",AA$4<$D8),0,INDEX('RAMP SCHEDULES'!$B$4:$M$13,MATCH($C8,'RAMP SCHEDULES'!$A$4:$A$13,0),MIN(12,AA$4-$D8+1))*$F8) -> 83334 | AB8: =IF(OR($C8="",AB$4<$D8),0,INDEX('RAMP SCHEDULES'!$B$4:$M$13,MATCH($C8,'RAMP SCHEDULES'!$A$4:$A$13,0),MIN(12,AB$4-$D8+1))*$F8) -> 83334 | ... AF8: =IF(OR($C8="",AF$4<$D8),0,INDEX('RAMP SCHEDULES'!$B$4:$M$13,MATCH($C8,'RAMP SCHEDULES'!$A$4:$A$13,0),MIN(12,AF$4-$D8+1))*$F8) -> 83334 | AG8: =SUM(I8:T8) -> 800004.8 | AH8: =SUM(U8:AF8) -> 1000006 | AI8: =AG8*$G8 -> 20000.12 | AJ8: =AH8*$G8 -> 25000.15
A9: Zach Schiff | B9: Account Executive - RAMP | C9: NEW AE | D9: -8 | E9: 0.8 | F9: 1 | G9: 0.025 | H9: =IF($C9="",0,12*INDEX('RAMP SCHEDULES'!$B$4:$M$13,MATCH($C9,'RAMP SCHEDULES'!$A$4:$A$13,0),12)) -> 1000008 | I9: =IF(OR($C9="",I$4<$D9),0,INDEX('RAMP SCHEDULES'!$B$4:$M$13,MATCH($C9,'RAMP SCHEDULES'!$A$4:$A$13,0),MIN(12,I$4-$D9+1))*$E9) -> 66666.4 | J9: =IF(OR($C9="",J$4<$D9),0,INDEX('RAMP SCHEDULES'!$B$4:$M$13,MATCH($C9,'RAMP SCHEDULES'!$A$4:$A$13,0),MIN(12,J$4-$D9+1))*$E9) -> 66666.4 | K9: =IF(OR($C9="",K$4<$D9),0,INDEX('RAMP SCHEDULES'!$B$4:$M$13,MATCH($C9,'RAMP SCHEDULES'!$A$4:$A$13,0),MIN(12,K$4-$D9+1))*$E9) -> 66667.2 | L9: =IF(OR($C9="",L$4<$D9),0,INDEX('RAMP SCHEDULES'!$B$4:$M$13,MATCH($C9,'RAMP SCHEDULES'!$A$4:$A$13,0),MIN(12,L$4-$D9+1))*$E9) -> 66667.2 | M9: =IF(OR($C9="",M$4<$D9),0,INDEX('RAMP SCHEDULES'!$B$4:$M$13,MATCH($C9,'RAMP SCHEDULES'!$A$4:$A$13,0),MIN(12,M$4-$D9+1))*$E9) -> 66667.2 | N9: =IF(OR($C9="",N$4<$D9),0,INDEX('RAMP SCHEDULES'!$B$4:$M$13,MATCH($C9,'RAMP SCHEDULES'!$A$4:$A$13,0),MIN(12,N$4-$D9+1))*$E9) -> 66667.2 | O9: =IF(OR($C9="",O$4<$D9),0,INDEX('RAMP SCHEDULES'!$B$4:$M$13,MATCH($C9,'RAMP SCHEDULES'!$A$4:$A$13,0),MIN(12,O$4-$D9+1))*$E9) -> 66667.2 | P9: =IF(OR($C9="",P$4<$D9),0,INDEX('RAMP SCHEDULES'!$B$4:$M$13,MATCH($C9,'RAMP SCHEDULES'!$A$4:$A$13,0),MIN(12,P$4-$D9+1))*$E9) -> 66667.2 | ... T9: =IF(OR($C9="",T$4<$D9),0,INDEX('RAMP SCHEDULES'!$B$4:$M$13,MATCH($C9,'RAMP SCHEDULES'!$A$4:$A$13,0),MIN(12,T$4-$D9+1))*$E9) -> 66667.2 | U9: =IF(OR($C9="",U$4<$D9),0,INDEX('RAMP SCHEDULES'!$B$4:$M$13,MATCH($C9,'RAMP SCHEDULES'!$A$4:$A$13,0),MIN(12,U$4-$D9+1))*$F9) -> 83333 | V9: =IF(OR($C9="",V$4<$D9),0,INDEX('RAMP SCHEDULES'!$B$4:$M$13,MATCH($C9,'RAMP SCHEDULES'!$A$4:$A$13,0),MIN(12,V$4-$D9+1))*$F9) -> 83333 | W9: =IF(OR($C9="",W$4<$D9),0,INDEX('RAMP SCHEDULES'!$B$4:$M$13,MATCH($C9,'RAMP SCHEDULES'!$A$4:$A$13,0),MIN(12,W$4-$D9+1))*$F9) -> 83334 | X9: =IF(OR($C9="",X$4<$D9),0,INDEX('RAMP SCHEDULES'!$B$4:$M$13,MATCH($C9,'RAMP SCHEDULES'!$A$4:$A$13,0),MIN(12,X$4-$D9+1))*$F9) -> 83334 | Y9: =IF(OR($C9="",Y$4<$D9),0,INDEX('RAMP SCHEDULES'!$B$4:$M$13,MATCH($C9,'RAMP SCHEDULES'!$A$4:$A$13,0),MIN(12,Y$4-$D9+1))*$F9) -> 83334 | Z9: =IF(OR($C9="",Z$4<$D9),0,INDEX('RAMP SCHEDULES'!$B$4:$M$13,MATCH($C9,'RAMP SCHEDULES'!$A$4:$A$13,0),MIN(12,Z$4-$D9+1))*$F9) -> 83334 | AA9: =IF(OR($C9="",AA$4<$D9),0,INDEX('RAMP SCHEDULES'!$B$4:$M$13,MATCH($C9,'RAMP SCHEDULES'!$A$4:$A$13,0),MIN(12,AA$4-$D9+1))*$F9) -> 83334 | AB9: =IF(OR($C9="",AB$4<$D9),0,INDEX('RAMP SCHEDULES'!$B$4:$M$13,MATCH($C9,'RAMP SCHEDULES'!$A$4:$A$13,0),MIN(12,AB$4-$D9+1))*$F9) -> 83334 | ... AF9: =IF(OR($C9="",AF$4<$D9),0,INDEX('RAMP SCHEDULES'!$B$4:$M$13,MATCH($C9,'RAMP SCHEDULES'!$A$4:$A$13,0),MIN(12,AF$4-$D9+1))*$F9) -> 83334 | AG9: =SUM(I9:T9) -> 800004.8 | AH9: =SUM(U9:AF9) -> 1000006 | AI9: =AG9*$G9 -> 20000.12 | AJ9: =AH9*$G9 -> 25000.15
A10: Kenny Hester | B10: Account Executive - RAMP | C10: NEW AE | D10: -4 | E10: 0.8 | F10: 1 | G10: 0.025 | H10: =IF($C10="",0,12*INDEX('RAMP SCHEDULES'!$B$4:$M$13,MATCH($C10,'RAMP SCHEDULES'!$A$4:$A$13,0),12)) -> 1000008 | I10: =IF(OR($C10="",I$4<$D10),0,INDEX('RAMP SCHEDULES'!$B$4:$M$13,MATCH($C10,'RAMP SCHEDULES'!$A$4:$A$13,0),MIN(12,I$4-$D10+1))*$E10) -> 36000 | J10: =IF(OR($C10="",J$4<$D10),0,INDEX('RAMP SCHEDULES'!$B$4:$M$13,MATCH($C10,'RAMP SCHEDULES'!$A$4:$A$13,0),MIN(12,J$4-$D10+1))*$E10) -> 40000 | K10: =IF(OR($C10="",K$4<$D10),0,INDEX('RAMP SCHEDULES'!$B$4:$M$13,MATCH($C10,'RAMP SCHEDULES'!$A$4:$A$13,0),MIN(12,K$4-$D10+1))*$E10) -> 44000 | L10: =IF(OR($C10="",L$4<$D10),0,INDEX('RAMP SCHEDULES'!$B$4:$M$13,MATCH($C10,'RAMP SCHEDULES'!$A$4:$A$13,0),MIN(12,L$4-$D10+1))*$E10) -> 56000 | M10: =IF(OR($C10="",M$4<$D10),0,INDEX('RAMP SCHEDULES'!$B$4:$M$13,MATCH($C10,'RAMP SCHEDULES'!$A$4:$A$13,0),MIN(12,M$4-$D10+1))*$E10) -> 66666.4 | N10: =IF(OR($C10="",N$4<$D10),0,INDEX('RAMP SCHEDULES'!$B$4:$M$13,MATCH($C10,'RAMP SCHEDULES'!$A$4:$A$13,0),MIN(12,N$4-$D10+1))*$E10) -> 66666.4 | O10: =IF(OR($C10="",O$4<$D10),0,INDEX('RAMP SCHEDULES'!$B$4:$M$13,MATCH($C10,'RAMP SCHEDULES'!$A$4:$A$13,0),MIN(12,O$4-$D10+1))*$E10) -> 66667.2 | P10: =IF(OR($C10="",P$4<$D10),0,INDEX('RAMP SCHEDULES'!$B$4:$M$13,MATCH($C10,'RAMP SCHEDULES'!$A$4:$A$13,0),MIN(12,P$4-$D10+1))*$E10) -> 66667.2 | ... T10: =IF(OR($C10="",T$4<$D10),0,INDEX('RAMP SCHEDULES'!$B$4:$M$13,MATCH($C10,'RAMP SCHEDULES'!$A$4:$A$13,0),MIN(12,T$4-$D10+1))*$E10) -> 66667.2 | U10: =IF(OR($C10="",U$4<$D10),0,INDEX('RAMP SCHEDULES'!$B$4:$M$13,MATCH($C10,'RAMP SCHEDULES'!$A$4:$A$13,0),MIN(12,U$4-$D10+1))*$F10) -> 45000 | V10: =IF(OR($C10="",V$4<$D10),0,INDEX('RAMP SCHEDULES'!$B$4:$M$13,MATCH($C10,'RAMP SCHEDULES'!$A$4:$A$13,0),MIN(12,V$4-$D10+1))*$F10) -> 50000 | W10: =IF(OR($C10="",W$4<$D10),0,INDEX('RAMP SCHEDULES'!$B$4:$M$13,MATCH($C10,'RAMP SCHEDULES'!$A$4:$A$13,0),MIN(12,W$4-$D10+1))*$F10) -> 55000 | X10: =IF(OR($C10="",X$4<$D10),0,INDEX('RAMP SCHEDULES'!$B$4:$M$13,MATCH($C10,'RAMP SCHEDULES'!$A$4:$A$13,0),MIN(12,X$4-$D10+1))*$F10) -> 70000 | Y10: =IF(OR($C10="",Y$4<$D10),0,INDEX('RAMP SCHEDULES'!$B$4:$M$13,MATCH($C10,'RAMP SCHEDULES'!$A$4:$A$13,0),MIN(12,Y$4-$D10+1))*$F10) -> 83333 | Z10: =IF(OR($C10="",Z$4<$D10),0,INDEX('RAMP SCHEDULES'!$B$4:$M$13,MATCH($C10,'RAMP SCHEDULES'!$A$4:$A$13,0),MIN(12,Z$4-$D10+1))*$F10) -> 83333 | AA10: =IF(OR($C10="",AA$4<$D10),0,INDEX('RAMP SCHEDULES'!$B$4:$M$13,MATCH($C10,'RAMP SCHEDULES'!$A$4:$A$13,0),MIN(12,AA$4-$D10+1))*$F10) -> 83334 | AB10: =IF(OR($C10="",AB$4<$D10),0,INDEX('RAMP SCHEDULES'!$B$4:$M$13,MATCH($C10,'RAMP SCHEDULES'!$A$4:$A$13,0),MIN(12,AB$4-$D10+1))*$F10) -> 83334 | ... AF10: =IF(OR($C10="",AF$4<$D10),0,INDEX('RAMP SCHEDULES'!$B$4:$M$13,MATCH($C10,'RAMP SCHEDULES'!$A$4:$A$13,0),MIN(12,AF$4-$D10+1))*$F10) -> 83334 | AG10: =SUM(I10:T10) -> 709336 | AH10: =SUM(U10:AF10) -> 886670 | AI10: =AG10*$G10 -> 17733.4 | AJ10: =AH10*$G10 -> 22166.75
A11: Brian Burke | B11: Account Executive - RAMP | C11: NEW AE | D11: -1 | E11: 0.8 | F11: 1 | G11: 0.025 | H11: =IF($C11="",0,12*INDEX('RAMP SCHEDULES'!$B$4:$M$13,MATCH($C11,'RAMP SCHEDULES'!$A$4:$A$13,0),12)) -> 1000008 | I11: =IF(OR($C11="",I$4<$D11),0,INDEX('RAMP SCHEDULES'!$B$4:$M$13,MATCH($C11,'RAMP SCHEDULES'!$A$4:$A$13,0),MIN(12,I$4-$D11+1))*$E11) -> 32000 | J11: =IF(OR($C11="",J$4<$D11),0,INDEX('RAMP SCHEDULES'!$B$4:$M$13,MATCH($C11,'RAMP SCHEDULES'!$A$4:$A$13,0),MIN(12,J$4-$D11+1))*$E11) -> 32000 | K11: =IF(OR($C11="",K$4<$D11),0,INDEX('RAMP SCHEDULES'!$B$4:$M$13,MATCH($C11,'RAMP SCHEDULES'!$A$4:$A$13,0),MIN(12,K$4-$D11+1))*$E11) -> 36000 | L11: =IF(OR($C11="",L$4<$D11),0,INDEX('RAMP SCHEDULES'!$B$4:$M$13,MATCH($C11,'RAMP SCHEDULES'!$A$4:$A$13,0),MIN(12,L$4-$D11+1))*$E11) -> 36000 | M11: =IF(OR($C11="",M$4<$D11),0,INDEX('RAMP SCHEDULES'!$B$4:$M$13,MATCH($C11,'RAMP SCHEDULES'!$A$4:$A$13,0),MIN(12,M$4-$D11+1))*$E11) -> 40000 | N11: =IF(OR($C11="",N$4<$D11),0,INDEX('RAMP SCHEDULES'!$B$4:$M$13,MATCH($C11,'RAMP SCHEDULES'!$A$4:$A$13,0),MIN(12,N$4-$D11+1))*$E11) -> 44000 | O11: =IF(OR($C11="",O$4<$D11),0,INDEX('RAMP SCHEDULES'!$B$4:$M$13,MATCH($C11,'RAMP SCHEDULES'!$A$4:$A$13,0),MIN(12,O$4-$D11+1))*$E11) -> 56000 | P11: =IF(OR($C11="",P$4<$D11),0,INDEX('RAMP SCHEDULES'!$B$4:$M$13,MATCH($C11,'RAMP SCHEDULES'!$A$4:$A$13,0),MIN(12,P$4-$D11+1))*$E11) -> 66666.4 | ... T11: =IF(OR($C11="",T$4<$D11),0,INDEX('RAMP SCHEDULES'!$B$4:$M$13,MATCH($C11,'RAMP SCHEDULES'!$A$4:$A$13,0),MIN(12,T$4-$D11+1))*$E11) -> 66667.2 | U11: =IF(OR($C11="",U$4<$D11),0,INDEX('RAMP SCHEDULES'!$B$4:$M$13,MATCH($C11,'RAMP SCHEDULES'!$A$4:$A$13,0),MIN(12,U$4-$D11+1))*$F11) -> 40000 | V11: =IF(OR($C11="",V$4<$D11),0,INDEX('RAMP SCHEDULES'!$B$4:$M$13,MATCH($C11,'RAMP SCHEDULES'!$A$4:$A$13,0),MIN(12,V$4-$D11+1))*$F11) -> 40000 | W11: =IF(OR($C11="",W$4<$D11),0,INDEX('RAMP SCHEDULES'!$B$4:$M$13,MATCH($C11,'RAMP SCHEDULES'!$A$4:$A$13,0),MIN(12,W$4-$D11+1))*$F11) -> 45000 | X11: =IF(OR($C11="",X$4<$D11),0,INDEX('RAMP SCHEDULES'!$B$4:$M$13,MATCH($C11,'RAMP SCHEDULES'!$A$4:$A$13,0),MIN(12,X$4-$D11+1))*$F11) -> 45000 | Y11: =IF(OR($C11="",Y$4<$D11),0,INDEX('RAMP SCHEDULES'!$B$4:$M$13,MATCH($C11,'RAMP SCHEDULES'!$A$4:$A$13,0),MIN(12,Y$4-$D11+1))*$F11) -> 50000 | Z11: =IF(OR($C11="",Z$4<$D11),0,INDEX('RAMP SCHEDULES'!$B$4:$M$13,MATCH($C11,'RAMP SCHEDULES'!$A$4:$A$13,0),MIN(12,Z$4-$D11+1))*$F11) -> 55000 | AA11: =IF(OR($C11="",AA$4<$D11),0,INDEX('RAMP SCHEDULES'!$B$4:$M$13,MATCH($C11,'RAMP SCHEDULES'!$A$4:$A$13,0),MIN(12,AA$4-$D11+1))*$F11) -> 70000 | AB11: =IF(OR($C11="",AB$4<$D11),0,INDEX('RAMP SCHEDULES'!$B$4:$M$13,MATCH($C11,'RAMP SCHEDULES'!$A$4:$A$13,0),MIN(12,AB$4-$D11+1))*$F11) -> 83333 | ... AF11: =IF(OR($C11="",AF$4<$D11),0,INDEX('RAMP SCHEDULES'!$B$4:$M$13,MATCH($C11,'RAMP SCHEDULES'!$A$4:$A$13,0),MIN(12,AF$4-$D11+1))*$F11) -> 83334 | AG11: =SUM(I11:T11) -> 609334.4 | AH11: =SUM(U11:AF11) -> 761668 | AI11: =AG11*$G11 -> 15233.36 | AJ11: =AH11*$G11 -> 19041.7
A12: Jonathan Pierce | B12: Account Executive - RAMP | C12: NEW AE | D12: 3 | E12: 0.8 | F12: 1 | G12: 0.025 | H12: =IF($C12="",0,12*INDEX('RAMP SCHEDULES'!$B$4:$M$13,MATCH($C12,'RAMP SCHEDULES'!$A$4:$A$13,0),12)) -> 1000008 | I12: =IF(OR($C12="",I$4<$D12),0,INDEX('RAMP SCHEDULES'!$B$4:$M$13,MATCH($C12,'RAMP SCHEDULES'!$A$4:$A$13,0),MIN(12,I$4-$D12+1))*$E12) -> 0 | J12: =IF(OR($C12="",J$4<$D12),0,INDEX('RAMP SCHEDULES'!$B$4:$M$13,MATCH($C12,'RAMP SCHEDULES'!$A$4:$A$13,0),MIN(12,J$4-$D12+1))*$E12) -> 0 | K12: =IF(OR($C12="",K$4<$D12),0,INDEX('RAMP SCHEDULES'!$B$4:$M$13,MATCH($C12,'RAMP SCHEDULES'!$A$4:$A$13,0),MIN(12,K$4-$D12+1))*$E12) -> 0 | L12: =IF(OR($C12="",L$4<$D12),0,INDEX('RAMP SCHEDULES'!$B$4:$M$13,MATCH($C12,'RAMP SCHEDULES'!$A$4:$A$13,0),MIN(12,L$4-$D12+1))*$E12) -> 24000 | M12: =IF(OR($C12="",M$4<$D12),0,INDEX('RAMP SCHEDULES'!$B$4:$M$13,MATCH($C12,'RAMP SCHEDULES'!$A$4:$A$13,0),MIN(12,M$4-$D12+1))*$E12) -> 32000 | N12: =IF(OR($C12="",N$4<$D12),0,INDEX('RAMP SCHEDULES'!$B$4:$M$13,MATCH($C12,'RAMP SCHEDULES'!$A$4:$A$13,0),MIN(12,N$4-$D12+1))*$E12) -> 32000 | O12: =IF(OR($C12="",O$4<$D12),0,INDEX('RAMP SCHEDULES'!$B$4:$M$13,MATCH($C12,'RAMP SCHEDULES'!$A$4:$A$13,0),MIN(12,O$4-$D12+1))*$E12) -> 36000 | P12: =IF(OR($C12="",P$4<$D12),0,INDEX('RAMP SCHEDULES'!$B$4:$M$13,MATCH($C12,'RAMP SCHEDULES'!$A$4:$A$13,0),MIN(12,P$4-$D12+1))*$E12) -> 36000 | ... T12: =IF(OR($C12="",T$4<$D12),0,INDEX('RAMP SCHEDULES'!$B$4:$M$13,MATCH($C12,'RAMP SCHEDULES'!$A$4:$A$13,0),MIN(12,T$4-$D12+1))*$E12) -> 66666.4 | U12: =IF(OR($C12="",U$4<$D12),0,INDEX('RAMP SCHEDULES'!$B$4:$M$13,MATCH($C12,'RAMP SCHEDULES'!$A$4:$A$13,0),MIN(12,U$4-$D12+1))*$F12) -> 0 | V12: =IF(OR($C12="",V$4<$D12),0,INDEX('RAMP SCHEDULES'!$B$4:$M$13,MATCH($C12,'RAMP SCHEDULES'!$A$4:$A$13,0),MIN(12,V$4-$D12+1))*$F12) -> 0 | W12: =IF(OR($C12="",W$4<$D12),0,INDEX('RAMP SCHEDULES'!$B$4:$M$13,MATCH($C12,'RAMP SCHEDULES'!$A$4:$A$13,0),MIN(12,W$4-$D12+1))*$F12) -> 0 | X12: =IF(OR($C12="",X$4<$D12),0,INDEX('RAMP SCHEDULES'!$B$4:$M$13,MATCH($C12,'RAMP SCHEDULES'!$A$4:$A$13,0),MIN(12,X$4-$D12+1))*$F12) -> 30000 | Y12: =IF(OR($C12="",Y$4<$D12),0,INDEX('RAMP SCHEDULES'!$B$4:$M$13,MATCH($C12,'RAMP SCHEDULES'!$A$4:$A$13,0),MIN(12,Y$4-$D12+1))*$F12) -> 40000 | Z12: =IF(OR($C12="",Z$4<$D12),0,INDEX('RAMP SCHEDULES'!$B$4:$M$13,MATCH($C12,'RAMP SCHEDULES'!$A$4:$A$13,0),MIN(12,Z$4-$D12+1))*$F12) -> 40000 | AA12: =IF(OR($C12="",AA$4<$D12),0,INDEX('RAMP SCHEDULES'!$B$4:$M$13,MATCH($C12,'RAMP SCHEDULES'!$A$4:$A$13,0),MIN(12,AA$4-$D12+1))*$F12) -> 45000 | AB12: =IF(OR($C12="",AB$4<$D12),0,INDEX('RAMP SCHEDULES'!$B$4:$M$13,MATCH($C12,'RAMP SCHEDULES'!$A$4:$A$13,0),MIN(12,AB$4-$D12+1))*$F12) -> 45000 | ... AF12: =IF(OR($C12="",AF$4<$D12),0,INDEX('RAMP SCHEDULES'!$B$4:$M$13,MATCH($C12,'RAMP SCHEDULES'!$A$4:$A$13,0),MIN(12,AF$4-$D12+1))*$F12) -> 83333 | AG12: =SUM(I12:T12) -> 366666.4 | AH12: =SUM(U12:AF12) -> 458333 | AI12: =AG12*$G12 -> 9166.66 | AJ12: =AH12*$G12 -> 11458.325
A13: Cory Anderson | B13: Account Executive - RAMP | C13: NEW AE | D13: 3 | E13: 0.8 | F13: 1 | G13: 0.025 | H13: =IF($C13="",0,12*INDEX('RAMP SCHEDULES'!$B$4:$M$13,MATCH($C13,'RAMP SCHEDULES'!$A$4:$A$13,0),12)) -> 1000008 | I13: =IF(OR($C13="",I$4<$D13),0,INDEX('RAMP SCHEDULES'!$B$4:$M$13,MATCH($C13,'RAMP SCHEDULES'!$A$4:$A$13,0),MIN(12,I$4-$D13+1))*$E13) -> 0 | J13: =IF(OR($C13="",J$4<$D13),0,INDEX('RAMP SCHEDULES'!$B$4:$M$13,MATCH($C13,'RAMP SCHEDULES'!$A$4:$A$13,0),MIN(12,J$4-$D13+1))*$E13) -> 0 | K13: =IF(OR($C13="",K$4<$D13),0,INDEX('RAMP SCHEDULES'!$B$4:$M$13,MATCH($C13,'RAMP SCHEDULES'!$A$4:$A$13,0),MIN(12,K$4-$D13+1))*$E13) -> 0 | L13: =IF(OR($C13="",L$4<$D13),0,INDEX('RAMP SCHEDULES'!$B$4:$M$13,MATCH($C13,'RAMP SCHEDULES'!$A$4:$A$13,0),MIN(12,L$4-$D13+1))*$E13) -> 24000 | M13: =IF(OR($C13="",M$4<$D13),0,INDEX('RAMP SCHEDULES'!$B$4:$M$13,MATCH($C13,'RAMP SCHEDULES'!$A$4:$A$13,0),MIN(12,M$4-$D13+1))*$E13) -> 32000 | N13: =IF(OR($C13="",N$4<$D13),0,INDEX('RAMP SCHEDULES'!$B$4:$M$13,MATCH($C13,'RAMP SCHEDULES'!$A$4:$A$13,0),MIN(12,N$4-$D13+1))*$E13) -> 32000 | O13: =IF(OR($C13="",O$4<$D13),0,INDEX('RAMP SCHEDULES'!$B$4:$M$13,MATCH($C13,'RAMP SCHEDULES'!$A$4:$A$13,0),MIN(12,O$4-$D13+1))*$E13) -> 36000 | P13: =IF(OR($C13="",P$4<$D13),0,INDEX('RAMP SCHEDULES'!$B$4:$M$13,MATCH($C13,'RAMP SCHEDULES'!$A$4:$A$13,0),MIN(12,P$4-$D13+1))*$E13) -> 36000 | ... T13: =IF(OR($C13="",T$4<$D13),0,INDEX('RAMP SCHEDULES'!$B$4:$M$13,MATCH($C13,'RAMP SCHEDULES'!$A$4:$A$13,0),MIN(12,T$4-$D13+1))*$E13) -> 66666.4 | U13: =IF(OR($C13="",U$4<$D13),0,INDEX('RAMP SCHEDULES'!$B$4:$M$13,MATCH($C13,'RAMP SCHEDULES'!$A$4:$A$13,0),MIN(12,U$4-$D13+1))*$F13) -> 0 | V13: =IF(OR($C13="",V$4<$D13),0,INDEX('RAMP SCHEDULES'!$B$4:$M$13,MATCH($C13,'RAMP SCHEDULES'!$A$4:$A$13,0),MIN(12,V$4-$D13+1))*$F13) -> 0 | W13: =IF(OR($C13="",W$4<$D13),0,INDEX('RAMP SCHEDULES'!$B$4:$M$13,MATCH($C13,'RAMP SCHEDULES'!$A$4:$A$13,0),MIN(12,W$4-$D13+1))*$F13) -> 0 | X13: =IF(OR($C13="",X$4<$D13),0,INDEX('RAMP SCHEDULES'!$B$4:$M$13,MATCH($C13,'RAMP SCHEDULES'!$A$4:$A$13,0),MIN(12,X$4-$D13+1))*$F13) -> 30000 | Y13: =IF(OR($C13="",Y$4<$D13),0,INDEX('RAMP SCHEDULES'!$B$4:$M$13,MATCH($C13,'RAMP SCHEDULES'!$A$4:$A$13,0),MIN(12,Y$4-$D13+1))*$F13) -> 40000 | Z13: =IF(OR($C13="",Z$4<$D13),0,INDEX('RAMP SCHEDULES'!$B$4:$M$13,MATCH($C13,'RAMP SCHEDULES'!$A$4:$A$13,0),MIN(12,Z$4-$D13+1))*$F13) -> 40000 | AA13: =IF(OR($C13="",AA$4<$D13),0,INDEX('RAMP SCHEDULES'!$B$4:$M$13,MATCH($C13,'RAMP SCHEDULES'!$A$4:$A$13,0),MIN(12,AA$4-$D13+1))*$F13) -> 45000 | AB13: =IF(OR($C13="",AB$4<$D13),0,INDEX('RAMP SCHEDULES'!$B$4:$M$13,MATCH($C13,'RAMP SCHEDULES'!$A$4:$A$13,0),MIN(12,AB$4-$D13+1))*$F13) -> 45000 | ... AF13: =IF(OR($C13="",AF$4<$D13),0,INDEX('RAMP SCHEDULES'!$B$4:$M$13,MATCH($C13,'RAMP SCHEDULES'!$A$4:$A$13,0),MIN(12,AF$4-$D13+1))*$F13) -> 83333 | AG13: =SUM(I13:T13) -> 366666.4 | AH13: =SUM(U13:AF13) -> 458333 | AI13: =AG13*$G13 -> 9166.66 | AJ13: =AH13*$G13 -> 11458.325
A14: Justin Atherton | B14: Account Executive - RAMP | C14: NEW AE | D14: -1 | E14: 0.8 | F14: 1 | G14: 0.025 | H14: =IF($C14="",0,12*INDEX('RAMP SCHEDULES'!$B$4:$M$13,MATCH($C14,'RAMP SCHEDULES'!$A$4:$A$13,0),12)) -> 1000008 | I14: =IF(OR($C14="",I$4<$D14),0,INDEX('RAMP SCHEDULES'!$B$4:$M$13,MATCH($C14,'RAMP SCHEDULES'!$A$4:$A$13,0),MIN(12,I$4-$D14+1))*$E14) -> 32000 | J14: =IF(OR($C14="",J$4<$D14),0,INDEX('RAMP SCHEDULES'!$B$4:$M$13,MATCH($C14,'RAMP SCHEDULES'!$A$4:$A$13,0),MIN(12,J$4-$D14+1))*$E14) -> 32000 | K14: =IF(OR($C14="",K$4<$D14),0,INDEX('RAMP SCHEDULES'!$B$4:$M$13,MATCH($C14,'RAMP SCHEDULES'!$A$4:$A$13,0),MIN(12,K$4-$D14+1))*$E14) -> 36000 | L14: =IF(OR($C14="",L$4<$D14),0,INDEX('RAMP SCHEDULES'!$B$4:$M$13,MATCH($C14,'RAMP SCHEDULES'!$A$4:$A$13,0),MIN(12,L$4-$D14+1))*$E14) -> 36000 | M14: =IF(OR($C14="",M$4<$D14),0,INDEX('RAMP SCHEDULES'!$B$4:$M$13,MATCH($C14,'RAMP SCHEDULES'!$A$4:$A$13,0),MIN(12,M$4-$D14+1))*$E14) -> 40000 | N14: =IF(OR($C14="",N$4<$D14),0,INDEX('RAMP SCHEDULES'!$B$4:$M$13,MATCH($C14,'RAMP SCHEDULES'!$A$4:$A$13,0),MIN(12,N$4-$D14+1))*$E14) -> 44000 | O14: =IF(OR($C14="",O$4<$D14),0,INDEX('RAMP SCHEDULES'!$B$4:$M$13,MATCH($C14,'RAMP SCHEDULES'!$A$4:$A$13,0),MIN(12,O$4-$D14+1))*$E14) -> 56000 | P14: =IF(OR($C14="",P$4<$D14),0,INDEX('RAMP SCHEDULES'!$B$4:$M$13,MATCH($C14,'RAMP SCHEDULES'!$A$4:$A$13,0),MIN(12,P$4-$D14+1))*$E14) -> 66666.4 | ... T14: =IF(OR($C14="",T$4<$D14),0,INDEX('RAMP SCHEDULES'!$B$4:$M$13,MATCH($C14,'RAMP SCHEDULES'!$A$4:$A$13,0),MIN(12,T$4-$D14+1))*$E14) -> 66667.2 | U14: =IF(OR($C14="",U$4<$D14),0,INDEX('RAMP SCHEDULES'!$B$4:$M$13,MATCH($C14,'RAMP SCHEDULES'!$A$4:$A$13,0),MIN(12,U$4-$D14+1))*$F14) -> 40000 | V14: =IF(OR($C14="",V$4<$D14),0,INDEX('RAMP SCHEDULES'!$B$4:$M$13,MATCH($C14,'RAMP SCHEDULES'!$A$4:$A$13,0),MIN(12,V$4-$D14+1))*$F14) -> 40000 | W14: =IF(OR($C14="",W$4<$D14),0,INDEX('RAMP SCHEDULES'!$B$4:$M$13,MATCH($C14,'RAMP SCHEDULES'!$A$4:$A$13,0),MIN(12,W$4-$D14+1))*$F14) -> 45000 | X14: =IF(OR($C14="",X$4<$D14),0,INDEX('RAMP SCHEDULES'!$B$4:$M$13,MATCH($C14,'RAMP SCHEDULES'!$A$4:$A$13,0),MIN(12,X$4-$D14+1))*$F14) -> 45000 | Y14: =IF(OR($C14="",Y$4<$D14),0,INDEX('RAMP SCHEDULES'!$B$4:$M$13,MATCH($C14,'RAMP SCHEDULES'!$A$4:$A$13,0),MIN(12,Y$4-$D14+1))*$F14) -> 50000 | Z14: =IF(OR($C14="",Z$4<$D14),0,INDEX('RAMP SCHEDULES'!$B$4:$M$13,MATCH($C14,'RAMP SCHEDULES'!$A$4:$A$13,0),MIN(12,Z$4-$D14+1))*$F14) -> 55000 | AA14: =IF(OR($C14="",AA$4<$D14),0,INDEX('RAMP SCHEDULES'!$B$4:$M$13,MATCH($C14,'RAMP SCHEDULES'!$A$4:$A$13,0),MIN(12,AA$4-$D14+1))*$F14) -> 70000 | AB14: =IF(OR($C14="",AB$4<$D14),0,INDEX('RAMP SCHEDULES'!$B$4:$M$13,MATCH($C14,'RAMP SCHEDULES'!$A$4:$A$13,0),MIN(12,AB$4-$D14+1))*$F14) -> 83333 | ... AF14: =IF(OR($C14="",AF$4<$D14),0,INDEX('RAMP SCHEDULES'!$B$4:$M$13,MATCH($C14,'RAMP SCHEDULES'!$A$4:$A$13,0),MIN(12,AF$4-$D14+1))*$F14) -> 83334 | AG14: =SUM(I14:T14) -> 609334.4 | AH14: =SUM(U14:AF14) -> 761668 | AI14: =AG14*$G14 -> 15233.36 | AJ14: =AH14*$G14 -> 19041.7
A15: TBD | B15: Account Executive - RAMP | C15: NEW AE | D15: 6 | E15: 0.8 | F15: 1 | G15: 0.025 | H15: =IF($C15="",0,12*INDEX('RAMP SCHEDULES'!$B$4:$M$13,MATCH($C15,'RAMP SCHEDULES'!$A$4:$A$13,0),12)) -> 1000008 | I15: =IF(OR($C15="",I$4<$D15),0,INDEX('RAMP SCHEDULES'!$B$4:$M$13,MATCH($C15,'RAMP SCHEDULES'!$A$4:$A$13,0),MIN(12,I$4-$D15+1))*$E15) -> 0 | J15: =IF(OR($C15="",J$4<$D15),0,INDEX('RAMP SCHEDULES'!$B$4:$M$13,MATCH($C15,'RAMP SCHEDULES'!$A$4:$A$13,0),MIN(12,J$4-$D15+1))*$E15) -> 0 | K15: =IF(OR($C15="",K$4<$D15),0,INDEX('RAMP SCHEDULES'!$B$4:$M$13,MATCH($C15,'RAMP SCHEDULES'!$A$4:$A$13,0),MIN(12,K$4-$D15+1))*$E15) -> 0 | L15: =IF(OR($C15="",L$4<$D15),0,INDEX('RAMP SCHEDULES'!$B$4:$M$13,MATCH($C15,'RAMP SCHEDULES'!$A$4:$A$13,0),MIN(12,L$4-$D15+1))*$E15) -> 0 | M15: =IF(OR($C15="",M$4<$D15),0,INDEX('RAMP SCHEDULES'!$B$4:$M$13,MATCH($C15,'RAMP SCHEDULES'!$A$4:$A$13,0),MIN(12,M$4-$D15+1))*$E15) -> 0 | N15: =IF(OR($C15="",N$4<$D15),0,INDEX('RAMP SCHEDULES'!$B$4:$M$13,MATCH($C15,'RAMP SCHEDULES'!$A$4:$A$13,0),MIN(12,N$4-$D15+1))*$E15) -> 0 | O15: =IF(OR($C15="",O$4<$D15),0,INDEX('RAMP SCHEDULES'!$B$4:$M$13,MATCH($C15,'RAMP SCHEDULES'!$A$4:$A$13,0),MIN(12,O$4-$D15+1))*$E15) -> 24000 | P15: =IF(OR($C15="",P$4<$D15),0,INDEX('RAMP SCHEDULES'!$B$4:$M$13,MATCH($C15,'RAMP SCHEDULES'!$A$4:$A$13,0),MIN(12,P$4-$D15+1))*$E15) -> 32000 | ... T15: =IF(OR($C15="",T$4<$D15),0,INDEX('RAMP SCHEDULES'!$B$4:$M$13,MATCH($C15,'RAMP SCHEDULES'!$A$4:$A$13,0),MIN(12,T$4-$D15+1))*$E15) -> 40000 | U15: =IF(OR($C15="",U$4<$D15),0,INDEX('RAMP SCHEDULES'!$B$4:$M$13,MATCH($C15,'RAMP SCHEDULES'!$A$4:$A$13,0),MIN(12,U$4-$D15+1))*$F15) -> 0 | V15: =IF(OR($C15="",V$4<$D15),0,INDEX('RAMP SCHEDULES'!$B$4:$M$13,MATCH($C15,'RAMP SCHEDULES'!$A$4:$A$13,0),MIN(12,V$4-$D15+1))*$F15) -> 0 | W15: =IF(OR($C15="",W$4<$D15),0,INDEX('RAMP SCHEDULES'!$B$4:$M$13,MATCH($C15,'RAMP SCHEDULES'!$A$4:$A$13,0),MIN(12,W$4-$D15+1))*$F15) -> 0 | X15: =IF(OR($C15="",X$4<$D15),0,INDEX('RAMP SCHEDULES'!$B$4:$M$13,MATCH($C15,'RAMP SCHEDULES'!$A$4:$A$13,0),MIN(12,X$4-$D15+1))*$F15) -> 0 | Y15: =IF(OR($C15="",Y$4<$D15),0,INDEX('RAMP SCHEDULES'!$B$4:$M$13,MATCH($C15,'RAMP SCHEDULES'!$A$4:$A$13,0),MIN(12,Y$4-$D15+1))*$F15) -> 0 | Z15: =IF(OR($C15="",Z$4<$D15),0,INDEX('RAMP SCHEDULES'!$B$4:$M$13,MATCH($C15,'RAMP SCHEDULES'!$A$4:$A$13,0),MIN(12,Z$4-$D15+1))*$F15) -> 0 | AA15: =IF(OR($C15="",AA$4<$D15),0,INDEX('RAMP SCHEDULES'!$B$4:$M$13,MATCH($C15,'RAMP SCHEDULES'!$A$4:$A$13,0),MIN(12,AA$4-$D15+1))*$F15) -> 30000 | AB15: =IF(OR($C15="",AB$4<$D15),0,INDEX('RAMP SCHEDULES'!$B$4:$M$13,MATCH($C15,'RAMP SCHEDULES'!$A$4:$A$13,0),MIN(12,AB$4-$D15+1))*$F15) -> 40000 | ... AF15: =IF(OR($C15="",AF$4<$D15),0,INDEX('RAMP SCHEDULES'!$B$4:$M$13,MATCH($C15,'RAMP SCHEDULES'!$A$4:$A$13,0),MIN(12,AF$4-$D15+1))*$F15) -> 50000 | AG15: =SUM(I15:T15) -> 200000 | AH15: =SUM(U15:AF15) -> 250000 | AI15: =AG15*$G15 -> 5000 | AJ15: =AH15*$G15 -> 6250
A16: TBD | B16: Account Executive - RAMP | C16: NEW AE | D16: 6 | E16: 0.8 | F16: 1 | G16: 0.025 | H16: =IF($C16="",0,12*INDEX('RAMP SCHEDULES'!$B$4:$M$13,MATCH($C16,'RAMP SCHEDULES'!$A$4:$A$13,0),12)) -> 1000008 | I16: =IF(OR($C16="",I$4<$D16),0,INDEX('RAMP SCHEDULES'!$B$4:$M$13,MATCH($C16,'RAMP SCHEDULES'!$A$4:$A$13,0),MIN(12,I$4-$D16+1))*$E16) -> 0 | J16: =IF(OR($C16="",J$4<$D16),0,INDEX('RAMP SCHEDULES'!$B$4:$M$13,MATCH($C16,'RAMP SCHEDULES'!$A$4:$A$13,0),MIN(12,J$4-$D16+1))*$E16) -> 0 | K16: =IF(OR($C16="",K$4<$D16),0,INDEX('RAMP SCHEDULES'!$B$4:$M$13,MATCH($C16,'RAMP SCHEDULES'!$A$4:$A$13,0),MIN(12,K$4-$D16+1))*$E16) -> 0 | L16: =IF(OR($C16="",L$4<$D16),0,INDEX('RAMP SCHEDULES'!$B$4:$M$13,MATCH($C16,'RAMP SCHEDULES'!$A$4:$A$13,0),MIN(12,L$4-$D16+1))*$E16) -> 0 | M16: =IF(OR($C16="",M$4<$D16),0,INDEX('RAMP SCHEDULES'!$B$4:$M$13,MATCH($C16,'RAMP SCHEDULES'!$A$4:$A$13,0),MIN(12,M$4-$D16+1))*$E16) -> 0 | N16: =IF(OR($C16="",N$4<$D16),0,INDEX('RAMP SCHEDULES'!$B$4:$M$13,MATCH($C16,'RAMP SCHEDULES'!$A$4:$A$13,0),MIN(12,N$4-$D16+1))*$E16) -> 0 | O16: =IF(OR($C16="",O$4<$D16),0,INDEX('RAMP SCHEDULES'!$B$4:$M$13,MATCH($C16,'RAMP SCHEDULES'!$A$4:$A$13,0),MIN(12,O$4-$D16+1))*$E16) -> 24000 | P16: =IF(OR($C16="",P$4<$D16),0,INDEX('RAMP SCHEDULES'!$B$4:$M$13,MATCH($C16,'RAMP SCHEDULES'!$A$4:$A$13,0),MIN(12,P$4-$D16+1))*$E16) -> 32000 | ... T16: =IF(OR($C16="",T$4<$D16),0,INDEX('RAMP SCHEDULES'!$B$4:$M$13,MATCH($C16,'RAMP SCHEDULES'!$A$4:$A$13,0),MIN(12,T$4-$D16+1))*$E16) -> 40000 | U16: =IF(OR($C16="",U$4<$D16),0,INDEX('RAMP SCHEDULES'!$B$4:$M$13,MATCH($C16,'RAMP SCHEDULES'!$A$4:$A$13,0),MIN(12,U$4-$D16+1))*$F16) -> 0 | V16: =IF(OR($C16="",V$4<$D16),0,INDEX('RAMP SCHEDULES'!$B$4:$M$13,MATCH($C16,'RAMP SCHEDULES'!$A$4:$A$13,0),MIN(12,V$4-$D16+1))*$F16) -> 0 | W16: =IF(OR($C16="",W$4<$D16),0,INDEX('RAMP SCHEDULES'!$B$4:$M$13,MATCH($C16,'RAMP SCHEDULES'!$A$4:$A$13,0),MIN(12,W$4-$D16+1))*$F16) -> 0 | X16: =IF(OR($C16="",X$4<$D16),0,INDEX('RAMP SCHEDULES'!$B$4:$M$13,MATCH($C16,'RAMP SCHEDULES'!$A$4:$A$13,0),MIN(12,X$4-$D16+1))*$F16) -> 0 | Y16: =IF(OR($C16="",Y$4<$D16),0,INDEX('RAMP SCHEDULES'!$B$4:$M$13,MATCH($C16,'RAMP SCHEDULES'!$A$4:$A$13,0),MIN(12,Y$4-$D16+1))*$F16) -> 0 | Z16: =IF(OR($C16="",Z$4<$D16),0,INDEX('RAMP SCHEDULES'!$B$4:$M$13,MATCH($C16,'RAMP SCHEDULES'!$A$4:$A$13,0),MIN(12,Z$4-$D16+1))*$F16) -> 0 | AA16: =IF(OR($C16="",AA$4<$D16),0,INDEX('RAMP SCHEDULES'!$B$4:$M$13,MATCH($C16,'RAMP SCHEDULES'!$A$4:$A$13,0),MIN(12,AA$4-$D16+1))*$F16) -> 30000 | AB16: =IF(OR($C16="",AB$4<$D16),0,INDEX('RAMP SCHEDULES'!$B$4:$M$13,MATCH($C16,'RAMP SCHEDULES'!$A$4:$A$13,0),MIN(12,AB$4-$D16+1))*$F16) -> 40000 | ... AF16: =IF(OR($C16="",AF$4<$D16),0,INDEX('RAMP SCHEDULES'!$B$4:$M$13,MATCH($C16,'RAMP SCHEDULES'!$A$4:$A$13,0),MIN(12,AF$4-$D16+1))*$F16) -> 50000 | AG16: =SUM(I16:T16) -> 200000 | AH16: =SUM(U16:AF16) -> 250000 | AI16: =AG16*$G16 -> 5000 | AJ16: =AH16*$G16 -> 6250
A17: Coalter Wilson | B17: Account Manager - 55K Base | C17: NEW AM | D17: -8 | E17: 0.8 | F17: 1 | G17: 0.015 | H17: =IF($C17="",0,12*INDEX('RAMP SCHEDULES'!$B$4:$M$13,MATCH($C17,'RAMP SCHEDULES'!$A$4:$A$13,0),12)) -> 1200000 | I17: =IF(OR($C17="",I$4<$D17),0,INDEX('RAMP SCHEDULES'!$B$4:$M$13,MATCH($C17,'RAMP SCHEDULES'!$A$4:$A$13,0),MIN(12,I$4-$D17+1))*$E17) -> 80000 | J17: =IF(OR($C17="",J$4<$D17),0,INDEX('RAMP SCHEDULES'!$B$4:$M$13,MATCH($C17,'RAMP SCHEDULES'!$A$4:$A$13,0),MIN(12,J$4-$D17+1))*$E17) -> 80000 | K17: =IF(OR($C17="",K$4<$D17),0,INDEX('RAMP SCHEDULES'!$B$4:$M$13,MATCH($C17,'RAMP SCHEDULES'!$A$4:$A$13,0),MIN(12,K$4-$D17+1))*$E17) -> 80000 | L17: =IF(OR($C17="",L$4<$D17),0,INDEX('RAMP SCHEDULES'!$B$4:$M$13,MATCH($C17,'RAMP SCHEDULES'!$A$4:$A$13,0),MIN(12,L$4-$D17+1))*$E17) -> 80000 | M17: =IF(OR($C17="",M$4<$D17),0,INDEX('RAMP SCHEDULES'!$B$4:$M$13,MATCH($C17,'RAMP SCHEDULES'!$A$4:$A$13,0),MIN(12,M$4-$D17+1))*$E17) -> 80000 | N17: =IF(OR($C17="",N$4<$D17),0,INDEX('RAMP SCHEDULES'!$B$4:$M$13,MATCH($C17,'RAMP SCHEDULES'!$A$4:$A$13,0),MIN(12,N$4-$D17+1))*$E17) -> 80000 | O17: =IF(OR($C17="",O$4<$D17),0,INDEX('RAMP SCHEDULES'!$B$4:$M$13,MATCH($C17,'RAMP SCHEDULES'!$A$4:$A$13,0),MIN(12,O$4-$D17+1))*$E17) -> 80000 | P17: =IF(OR($C17="",P$4<$D17),0,INDEX('RAMP SCHEDULES'!$B$4:$M$13,MATCH($C17,'RAMP SCHEDULES'!$A$4:$A$13,0),MIN(12,P$4-$D17+1))*$E17) -> 80000 | ... T17: =IF(OR($C17="",T$4<$D17),0,INDEX('RAMP SCHEDULES'!$B$4:$M$13,MATCH($C17,'RAMP SCHEDULES'!$A$4:$A$13,0),MIN(12,T$4-$D17+1))*$E17) -> 80000 | U17: =IF(OR($C17="",U$4<$D17),0,INDEX('RAMP SCHEDULES'!$B$4:$M$13,MATCH($C17,'RAMP SCHEDULES'!$A$4:$A$13,0),MIN(12,U$4-$D17+1))*$F17) -> 100000 | V17: =IF(OR($C17="",V$4<$D17),0,INDEX('RAMP SCHEDULES'!$B$4:$M$13,MATCH($C17,'RAMP SCHEDULES'!$A$4:$A$13,0),MIN(12,V$4-$D17+1))*$F17) -> 100000 | W17: =IF(OR($C17="",W$4<$D17),0,INDEX('RAMP SCHEDULES'!$B$4:$M$13,MATCH($C17,'RAMP SCHEDULES'!$A$4:$A$13,0),MIN(12,W$4-$D17+1))*$F17) -> 100000 | X17: =IF(OR($C17="",X$4<$D17),0,INDEX('RAMP SCHEDULES'!$B$4:$M$13,MATCH($C17,'RAMP SCHEDULES'!$A$4:$A$13,0),MIN(12,X$4-$D17+1))*$F17) -> 100000 | Y17: =IF(OR($C17="",Y$4<$D17),0,INDEX('RAMP SCHEDULES'!$B$4:$M$13,MATCH($C17,'RAMP SCHEDULES'!$A$4:$A$13,0),MIN(12,Y$4-$D17+1))*$F17) -> 100000 | Z17: =IF(OR($C17="",Z$4<$D17),0,INDEX('RAMP SCHEDULES'!$B$4:$M$13,MATCH($C17,'RAMP SCHEDULES'!$A$4:$A$13,0),MIN(12,Z$4-$D17+1))*$F17) -> 100000 | AA17: =IF(OR($C17="",AA$4<$D17),0,INDEX('RAMP SCHEDULES'!$B$4:$M$13,MATCH($C17,'RAMP SCHEDULES'!$A$4:$A$13,0),MIN(12,AA$4-$D17+1))*$F17) -> 100000 | AB17: =IF(OR($C17="",AB$4<$D17),0,INDEX('RAMP SCHEDULES'!$B$4:$M$13,MATCH($C17,'RAMP SCHEDULES'!$A$4:$A$13,0),MIN(12,AB$4-$D17+1))*$F17) -> 100000 | ... AF17: =IF(OR($C17="",AF$4<$D17),0,INDEX('RAMP SCHEDULES'!$B$4:$M$13,MATCH($C17,'RAMP SCHEDULES'!$A$4:$A$13,0),MIN(12,AF$4-$D17+1))*$F17) -> 100000 | AG17: =SUM(I17:T17) -> 960000 | AH17: =SUM(U17:AF17) -> 1200000 | AI17: =AG17*$G17 -> 14400 | AJ17: =AH17*$G17 -> 18000
